{"level":"ERROR","location":"[on_open:1510] data_ws","message":"'FyersDataSocket' object has no attribute 'holdings'","timestamp":"2024-03-31 10:24:52,084+0530","service":"FyersDataSocket","exception":"Traceback (most recent call last):\n  File \"C:\\Users\\HP\\AppData\\Local\\Programs\\Python\\Python311\\Lib\\site-packages\\flask_socketio\\__init__.py\", line 823, in _handle_event\n    ret = handler(auth)\n          ^^^^^^^^^^^^^\nTypeError: LiveDataNamespace.on_connect() takes 1 positional argument but 2 were given\n\nDuring handling of the above exception, another exception occurred:\n\nTraceback (most recent call last):\n  File \"C:\\Users\\HP\\AppData\\Local\\Programs\\Python\\Python311\\Lib\\site-packages\\fyers_apiv3\\FyersWebsocket\\data_ws.py\", line 1508, in on_open\n    self.OnOpen()\n  File \"E:\\Github\\Stock-analyzing-website\\Back_end\\live_stock.py\", line 61, in onopen\n    fyers.holdings()\n    ^^^^^^^^^^^^^^\nAttributeError: 'FyersDataSocket' object has no attribute 'holdings'","exception_name":"AttributeError"}
{"level":"ERROR","location":"[connect:1529] data_ws","message":"Object of type AttributeError is not JSON serializable","timestamp":"2024-03-31 10:24:52,111+0530","service":"FyersDataSocket","exception":"Traceback (most recent call last):\n  File \"C:\\Users\\HP\\AppData\\Local\\Programs\\Python\\Python311\\Lib\\site-packages\\flask_socketio\\__init__.py\", line 823, in _handle_event\n    ret = handler(auth)\n          ^^^^^^^^^^^^^\nTypeError: LiveDataNamespace.on_connect() takes 1 positional argument but 2 were given\n\nDuring handling of the above exception, another exception occurred:\n\nTraceback (most recent call last):\n  File \"C:\\Users\\HP\\AppData\\Local\\Programs\\Python\\Python311\\Lib\\site-packages\\fyers_apiv3\\FyersWebsocket\\data_ws.py\", line 1508, in on_open\n    self.OnOpen()\n  File \"E:\\Github\\Stock-analyzing-website\\Back_end\\live_stock.py\", line 61, in onopen\n    fyers.holdings()\n    ^^^^^^^^^^^^^^\nAttributeError: 'FyersDataSocket' object has no attribute 'holdings'\n\nDuring handling of the above exception, another exception occurred:\n\nTraceback (most recent call last):\n  File \"C:\\Users\\HP\\AppData\\Local\\Programs\\Python\\Python311\\Lib\\site-packages\\fyers_apiv3\\FyersWebsocket\\data_ws.py\", line 1526, in connect\n    self.on_open()\n  File \"C:\\Users\\HP\\AppData\\Local\\Programs\\Python\\Python311\\Lib\\site-packages\\fyers_apiv3\\FyersWebsocket\\data_ws.py\", line 1511, in on_open\n    self.On_error(e)\n  File \"C:\\Users\\HP\\AppData\\Local\\Programs\\Python\\Python311\\Lib\\site-packages\\fyers_apiv3\\FyersWebsocket\\data_ws.py\", line 1492, in On_error\n    self.OnError(message)\n  File \"E:\\Github\\Stock-analyzing-website\\Back_end\\live_stock.py\", line 45, in onerror\n    self.emit('message', message)\n  File \"C:\\Users\\HP\\AppData\\Local\\Programs\\Python\\Python311\\Lib\\site-packages\\flask_socketio\\namespace.py\", line 31, in emit\n    return self.socketio.emit(event, data, room=room,\n           ^^^^^^^^^^^^^^^^^^^^^^^^^^^^^^^^^^^^^^^^^^\n  File \"C:\\Users\\HP\\AppData\\Local\\Programs\\Python\\Python311\\Lib\\site-packages\\flask_socketio\\__init__.py\", line 462, in emit\n    self.server.emit(event, *args, namespace=namespace, to=to,\n  File \"C:\\Users\\HP\\AppData\\Local\\Programs\\Python\\Python311\\Lib\\site-packages\\socketio\\server.py\", line 163, in emit\n    self.manager.emit(event, data, namespace, room=room,\n  File \"C:\\Users\\HP\\AppData\\Local\\Programs\\Python\\Python311\\Lib\\site-packages\\socketio\\manager.py\", line 43, in emit\n    encoded_packet = pkt.encode()\n                     ^^^^^^^^^^^^\n  File \"C:\\Users\\HP\\AppData\\Local\\Programs\\Python\\Python311\\Lib\\site-packages\\socketio\\packet.py\", line 64, in encode\n    encoded_packet += self.json.dumps(data, separators=(',', ':'))\n                      ^^^^^^^^^^^^^^^^^^^^^^^^^^^^^^^^^^^^^^^^^^^^\n  File \"C:\\Users\\HP\\AppData\\Local\\Programs\\Python\\Python311\\Lib\\json\\__init__.py\", line 238, in dumps\n    **kw).encode(obj)\n          ^^^^^^^^^^^\n  File \"C:\\Users\\HP\\AppData\\Local\\Programs\\Python\\Python311\\Lib\\json\\encoder.py\", line 200, in encode\n    chunks = self.iterencode(o, _one_shot=True)\n             ^^^^^^^^^^^^^^^^^^^^^^^^^^^^^^^^^^\n  File \"C:\\Users\\HP\\AppData\\Local\\Programs\\Python\\Python311\\Lib\\json\\encoder.py\", line 258, in iterencode\n    return _iterencode(o, 0)\n           ^^^^^^^^^^^^^^^^^\n  File \"C:\\Users\\HP\\AppData\\Local\\Programs\\Python\\Python311\\Lib\\json\\encoder.py\", line 180, in default\n    raise TypeError(f'Object of type {o.__class__.__name__} '\nTypeError: Object of type AttributeError is not JSON serializable","exception_name":"TypeError"}
{"level":"ERROR","location":"[on_open:1510] data_ws","message":"'FyersDataSocket' object has no attribute 'holdings'","timestamp":"2024-03-31 10:24:54,391+0530","service":"FyersDataSocket","exception":"Traceback (most recent call last):\n  File \"C:\\Users\\HP\\AppData\\Local\\Programs\\Python\\Python311\\Lib\\site-packages\\flask_socketio\\__init__.py\", line 823, in _handle_event\n    ret = handler(auth)\n          ^^^^^^^^^^^^^\nTypeError: LiveDataNamespace.on_connect() takes 1 positional argument but 2 were given\n\nDuring handling of the above exception, another exception occurred:\n\nTraceback (most recent call last):\n  File \"C:\\Users\\HP\\AppData\\Local\\Programs\\Python\\Python311\\Lib\\site-packages\\fyers_apiv3\\FyersWebsocket\\data_ws.py\", line 1508, in on_open\n    self.OnOpen()\n  File \"E:\\Github\\Stock-analyzing-website\\Back_end\\live_stock.py\", line 61, in onopen\n    fyers.holdings()\n    ^^^^^^^^^^^^^^\nAttributeError: 'FyersDataSocket' object has no attribute 'holdings'\n\nDuring handling of the above exception, another exception occurred:\n\nTraceback (most recent call last):\n  File \"C:\\Users\\HP\\AppData\\Local\\Programs\\Python\\Python311\\Lib\\site-packages\\fyers_apiv3\\FyersWebsocket\\data_ws.py\", line 1526, in connect\n    self.on_open()\n  File \"C:\\Users\\HP\\AppData\\Local\\Programs\\Python\\Python311\\Lib\\site-packages\\fyers_apiv3\\FyersWebsocket\\data_ws.py\", line 1511, in on_open\n    self.On_error(e)\n  File \"C:\\Users\\HP\\AppData\\Local\\Programs\\Python\\Python311\\Lib\\site-packages\\fyers_apiv3\\FyersWebsocket\\data_ws.py\", line 1492, in On_error\n    self.OnError(message)\n  File \"E:\\Github\\Stock-analyzing-website\\Back_end\\live_stock.py\", line 45, in onerror\n    self.emit('message', message)\n  File \"C:\\Users\\HP\\AppData\\Local\\Programs\\Python\\Python311\\Lib\\site-packages\\flask_socketio\\namespace.py\", line 31, in emit\n    return self.socketio.emit(event, data, room=room,\n           ^^^^^^^^^^^^^^^^^^^^^^^^^^^^^^^^^^^^^^^^^^\n  File \"C:\\Users\\HP\\AppData\\Local\\Programs\\Python\\Python311\\Lib\\site-packages\\flask_socketio\\__init__.py\", line 462, in emit\n    self.server.emit(event, *args, namespace=namespace, to=to,\n  File \"C:\\Users\\HP\\AppData\\Local\\Programs\\Python\\Python311\\Lib\\site-packages\\socketio\\server.py\", line 163, in emit\n    self.manager.emit(event, data, namespace, room=room,\n  File \"C:\\Users\\HP\\AppData\\Local\\Programs\\Python\\Python311\\Lib\\site-packages\\socketio\\manager.py\", line 43, in emit\n    encoded_packet = pkt.encode()\n                     ^^^^^^^^^^^^\n  File \"C:\\Users\\HP\\AppData\\Local\\Programs\\Python\\Python311\\Lib\\site-packages\\socketio\\packet.py\", line 64, in encode\n    encoded_packet += self.json.dumps(data, separators=(',', ':'))\n                      ^^^^^^^^^^^^^^^^^^^^^^^^^^^^^^^^^^^^^^^^^^^^\n  File \"C:\\Users\\HP\\AppData\\Local\\Programs\\Python\\Python311\\Lib\\json\\__init__.py\", line 238, in dumps\n    **kw).encode(obj)\n          ^^^^^^^^^^^\n  File \"C:\\Users\\HP\\AppData\\Local\\Programs\\Python\\Python311\\Lib\\json\\encoder.py\", line 200, in encode\n    chunks = self.iterencode(o, _one_shot=True)\n             ^^^^^^^^^^^^^^^^^^^^^^^^^^^^^^^^^^\n  File \"C:\\Users\\HP\\AppData\\Local\\Programs\\Python\\Python311\\Lib\\json\\encoder.py\", line 258, in iterencode\n    return _iterencode(o, 0)\n           ^^^^^^^^^^^^^^^^^\n  File \"C:\\Users\\HP\\AppData\\Local\\Programs\\Python\\Python311\\Lib\\json\\encoder.py\", line 180, in default\n    raise TypeError(f'Object of type {o.__class__.__name__} '\nTypeError: Object of type AttributeError is not JSON serializable\n\nDuring handling of the above exception, another exception occurred:\n\nTraceback (most recent call last):\n  File \"C:\\Users\\HP\\AppData\\Local\\Programs\\Python\\Python311\\Lib\\site-packages\\socketio\\server.py\", line 534, in _handle_connect\n    success = self._trigger_event(\n              ^^^^^^^^^^^^^^^^^^^^\n  File \"C:\\Users\\HP\\AppData\\Local\\Programs\\Python\\Python311\\Lib\\site-packages\\socketio\\server.py\", line 615, in _trigger_event\n    return handler.trigger_event(event, *args)\n           ^^^^^^^^^^^^^^^^^^^^^^^^^^^^^^^^^^^\n  File \"C:\\Users\\HP\\AppData\\Local\\Programs\\Python\\Python311\\Lib\\site-packages\\flask_socketio\\namespace.py\", line 25, in trigger_event\n    return self.socketio._handle_event(handler, event, self.namespace,\n           ^^^^^^^^^^^^^^^^^^^^^^^^^^^^^^^^^^^^^^^^^^^^^^^^^^^^^^^^^^^\n  File \"C:\\Users\\HP\\AppData\\Local\\Programs\\Python\\Python311\\Lib\\site-packages\\flask_socketio\\__init__.py\", line 825, in _handle_event\n    ret = handler()\n          ^^^^^^^^^\n  File \"E:\\Github\\Stock-analyzing-website\\Back_end\\live_stock.py\", line 34, in on_connect\n    fyers.connect()\n  File \"C:\\Users\\HP\\AppData\\Local\\Programs\\Python\\Python311\\Lib\\site-packages\\fyers_apiv3\\FyersWebsocket\\data_ws.py\", line 1530, in connect\n    self.On_error(e)\n  File \"C:\\Users\\HP\\AppData\\Local\\Programs\\Python\\Python311\\Lib\\site-packages\\fyers_apiv3\\FyersWebsocket\\data_ws.py\", line 1492, in On_error\n    self.OnError(message)\n  File \"E:\\Github\\Stock-analyzing-website\\Back_end\\live_stock.py\", line 45, in onerror\n    self.emit('message', message)\n  File \"C:\\Users\\HP\\AppData\\Local\\Programs\\Python\\Python311\\Lib\\site-packages\\flask_socketio\\namespace.py\", line 31, in emit\n    return self.socketio.emit(event, data, room=room,\n           ^^^^^^^^^^^^^^^^^^^^^^^^^^^^^^^^^^^^^^^^^^\n  File \"C:\\Users\\HP\\AppData\\Local\\Programs\\Python\\Python311\\Lib\\site-packages\\flask_socketio\\__init__.py\", line 462, in emit\n    self.server.emit(event, *args, namespace=namespace, to=to,\n  File \"C:\\Users\\HP\\AppData\\Local\\Programs\\Python\\Python311\\Lib\\site-packages\\socketio\\server.py\", line 163, in emit\n    self.manager.emit(event, data, namespace, room=room,\n  File \"C:\\Users\\HP\\AppData\\Local\\Programs\\Python\\Python311\\Lib\\site-packages\\socketio\\manager.py\", line 43, in emit\n    encoded_packet = pkt.encode()\n                     ^^^^^^^^^^^^\n  File \"C:\\Users\\HP\\AppData\\Local\\Programs\\Python\\Python311\\Lib\\site-packages\\socketio\\packet.py\", line 64, in encode\n    encoded_packet += self.json.dumps(data, separators=(',', ':'))\n                      ^^^^^^^^^^^^^^^^^^^^^^^^^^^^^^^^^^^^^^^^^^^^\n  File \"C:\\Users\\HP\\AppData\\Local\\Programs\\Python\\Python311\\Lib\\json\\__init__.py\", line 238, in dumps\n    **kw).encode(obj)\n          ^^^^^^^^^^^\n  File \"C:\\Users\\HP\\AppData\\Local\\Programs\\Python\\Python311\\Lib\\json\\encoder.py\", line 200, in encode\n    chunks = self.iterencode(o, _one_shot=True)\n             ^^^^^^^^^^^^^^^^^^^^^^^^^^^^^^^^^^\n  File \"C:\\Users\\HP\\AppData\\Local\\Programs\\Python\\Python311\\Lib\\json\\encoder.py\", line 258, in iterencode\n    return _iterencode(o, 0)\n           ^^^^^^^^^^^^^^^^^\n  File \"C:\\Users\\HP\\AppData\\Local\\Programs\\Python\\Python311\\Lib\\json\\encoder.py\", line 180, in default\n    raise TypeError(f'Object of type {o.__class__.__name__} '\nTypeError: Object of type TypeError is not JSON serializable\n\nDuring handling of the above exception, another exception occurred:\n\nTraceback (most recent call last):\n  File \"C:\\Users\\HP\\AppData\\Local\\Programs\\Python\\Python311\\Lib\\site-packages\\flask_socketio\\__init__.py\", line 823, in _handle_event\n    ret = handler(auth)\n          ^^^^^^^^^^^^^\nTypeError: LiveDataNamespace.on_connect() takes 1 positional argument but 2 were given\n\nDuring handling of the above exception, another exception occurred:\n\nTraceback (most recent call last):\n  File \"C:\\Users\\HP\\AppData\\Local\\Programs\\Python\\Python311\\Lib\\site-packages\\fyers_apiv3\\FyersWebsocket\\data_ws.py\", line 1508, in on_open\n    self.OnOpen()\n  File \"E:\\Github\\Stock-analyzing-website\\Back_end\\live_stock.py\", line 61, in onopen\n    fyers.holdings()\n    ^^^^^^^^^^^^^^\nAttributeError: 'FyersDataSocket' object has no attribute 'holdings'","exception_name":"AttributeError"}
{"level":"ERROR","location":"[connect:1529] data_ws","message":"Object of type AttributeError is not JSON serializable","timestamp":"2024-03-31 10:24:54,410+0530","service":"FyersDataSocket","exception":"Traceback (most recent call last):\n  File \"C:\\Users\\HP\\AppData\\Local\\Programs\\Python\\Python311\\Lib\\site-packages\\flask_socketio\\__init__.py\", line 823, in _handle_event\n    ret = handler(auth)\n          ^^^^^^^^^^^^^\nTypeError: LiveDataNamespace.on_connect() takes 1 positional argument but 2 were given\n\nDuring handling of the above exception, another exception occurred:\n\nTraceback (most recent call last):\n  File \"C:\\Users\\HP\\AppData\\Local\\Programs\\Python\\Python311\\Lib\\site-packages\\fyers_apiv3\\FyersWebsocket\\data_ws.py\", line 1508, in on_open\n    self.OnOpen()\n  File \"E:\\Github\\Stock-analyzing-website\\Back_end\\live_stock.py\", line 61, in onopen\n    fyers.holdings()\n    ^^^^^^^^^^^^^^\nAttributeError: 'FyersDataSocket' object has no attribute 'holdings'\n\nDuring handling of the above exception, another exception occurred:\n\nTraceback (most recent call last):\n  File \"C:\\Users\\HP\\AppData\\Local\\Programs\\Python\\Python311\\Lib\\site-packages\\fyers_apiv3\\FyersWebsocket\\data_ws.py\", line 1526, in connect\n    self.on_open()\n  File \"C:\\Users\\HP\\AppData\\Local\\Programs\\Python\\Python311\\Lib\\site-packages\\fyers_apiv3\\FyersWebsocket\\data_ws.py\", line 1511, in on_open\n    self.On_error(e)\n  File \"C:\\Users\\HP\\AppData\\Local\\Programs\\Python\\Python311\\Lib\\site-packages\\fyers_apiv3\\FyersWebsocket\\data_ws.py\", line 1492, in On_error\n    self.OnError(message)\n  File \"E:\\Github\\Stock-analyzing-website\\Back_end\\live_stock.py\", line 45, in onerror\n    self.emit('message', message)\n  File \"C:\\Users\\HP\\AppData\\Local\\Programs\\Python\\Python311\\Lib\\site-packages\\flask_socketio\\namespace.py\", line 31, in emit\n    return self.socketio.emit(event, data, room=room,\n           ^^^^^^^^^^^^^^^^^^^^^^^^^^^^^^^^^^^^^^^^^^\n  File \"C:\\Users\\HP\\AppData\\Local\\Programs\\Python\\Python311\\Lib\\site-packages\\flask_socketio\\__init__.py\", line 462, in emit\n    self.server.emit(event, *args, namespace=namespace, to=to,\n  File \"C:\\Users\\HP\\AppData\\Local\\Programs\\Python\\Python311\\Lib\\site-packages\\socketio\\server.py\", line 163, in emit\n    self.manager.emit(event, data, namespace, room=room,\n  File \"C:\\Users\\HP\\AppData\\Local\\Programs\\Python\\Python311\\Lib\\site-packages\\socketio\\manager.py\", line 43, in emit\n    encoded_packet = pkt.encode()\n                     ^^^^^^^^^^^^\n  File \"C:\\Users\\HP\\AppData\\Local\\Programs\\Python\\Python311\\Lib\\site-packages\\socketio\\packet.py\", line 64, in encode\n    encoded_packet += self.json.dumps(data, separators=(',', ':'))\n                      ^^^^^^^^^^^^^^^^^^^^^^^^^^^^^^^^^^^^^^^^^^^^\n  File \"C:\\Users\\HP\\AppData\\Local\\Programs\\Python\\Python311\\Lib\\json\\__init__.py\", line 238, in dumps\n    **kw).encode(obj)\n          ^^^^^^^^^^^\n  File \"C:\\Users\\HP\\AppData\\Local\\Programs\\Python\\Python311\\Lib\\json\\encoder.py\", line 200, in encode\n    chunks = self.iterencode(o, _one_shot=True)\n             ^^^^^^^^^^^^^^^^^^^^^^^^^^^^^^^^^^\n  File \"C:\\Users\\HP\\AppData\\Local\\Programs\\Python\\Python311\\Lib\\json\\encoder.py\", line 258, in iterencode\n    return _iterencode(o, 0)\n           ^^^^^^^^^^^^^^^^^\n  File \"C:\\Users\\HP\\AppData\\Local\\Programs\\Python\\Python311\\Lib\\json\\encoder.py\", line 180, in default\n    raise TypeError(f'Object of type {o.__class__.__name__} '\nTypeError: Object of type AttributeError is not JSON serializable\n\nDuring handling of the above exception, another exception occurred:\n\nTraceback (most recent call last):\n  File \"C:\\Users\\HP\\AppData\\Local\\Programs\\Python\\Python311\\Lib\\site-packages\\socketio\\server.py\", line 534, in _handle_connect\n    success = self._trigger_event(\n              ^^^^^^^^^^^^^^^^^^^^\n  File \"C:\\Users\\HP\\AppData\\Local\\Programs\\Python\\Python311\\Lib\\site-packages\\socketio\\server.py\", line 615, in _trigger_event\n    return handler.trigger_event(event, *args)\n           ^^^^^^^^^^^^^^^^^^^^^^^^^^^^^^^^^^^\n  File \"C:\\Users\\HP\\AppData\\Local\\Programs\\Python\\Python311\\Lib\\site-packages\\flask_socketio\\namespace.py\", line 25, in trigger_event\n    return self.socketio._handle_event(handler, event, self.namespace,\n           ^^^^^^^^^^^^^^^^^^^^^^^^^^^^^^^^^^^^^^^^^^^^^^^^^^^^^^^^^^^\n  File \"C:\\Users\\HP\\AppData\\Local\\Programs\\Python\\Python311\\Lib\\site-packages\\flask_socketio\\__init__.py\", line 825, in _handle_event\n    ret = handler()\n          ^^^^^^^^^\n  File \"E:\\Github\\Stock-analyzing-website\\Back_end\\live_stock.py\", line 34, in on_connect\n    fyers.connect()\n  File \"C:\\Users\\HP\\AppData\\Local\\Programs\\Python\\Python311\\Lib\\site-packages\\fyers_apiv3\\FyersWebsocket\\data_ws.py\", line 1530, in connect\n    self.On_error(e)\n  File \"C:\\Users\\HP\\AppData\\Local\\Programs\\Python\\Python311\\Lib\\site-packages\\fyers_apiv3\\FyersWebsocket\\data_ws.py\", line 1492, in On_error\n    self.OnError(message)\n  File \"E:\\Github\\Stock-analyzing-website\\Back_end\\live_stock.py\", line 45, in onerror\n    self.emit('message', message)\n  File \"C:\\Users\\HP\\AppData\\Local\\Programs\\Python\\Python311\\Lib\\site-packages\\flask_socketio\\namespace.py\", line 31, in emit\n    return self.socketio.emit(event, data, room=room,\n           ^^^^^^^^^^^^^^^^^^^^^^^^^^^^^^^^^^^^^^^^^^\n  File \"C:\\Users\\HP\\AppData\\Local\\Programs\\Python\\Python311\\Lib\\site-packages\\flask_socketio\\__init__.py\", line 462, in emit\n    self.server.emit(event, *args, namespace=namespace, to=to,\n  File \"C:\\Users\\HP\\AppData\\Local\\Programs\\Python\\Python311\\Lib\\site-packages\\socketio\\server.py\", line 163, in emit\n    self.manager.emit(event, data, namespace, room=room,\n  File \"C:\\Users\\HP\\AppData\\Local\\Programs\\Python\\Python311\\Lib\\site-packages\\socketio\\manager.py\", line 43, in emit\n    encoded_packet = pkt.encode()\n                     ^^^^^^^^^^^^\n  File \"C:\\Users\\HP\\AppData\\Local\\Programs\\Python\\Python311\\Lib\\site-packages\\socketio\\packet.py\", line 64, in encode\n    encoded_packet += self.json.dumps(data, separators=(',', ':'))\n                      ^^^^^^^^^^^^^^^^^^^^^^^^^^^^^^^^^^^^^^^^^^^^\n  File \"C:\\Users\\HP\\AppData\\Local\\Programs\\Python\\Python311\\Lib\\json\\__init__.py\", line 238, in dumps\n    **kw).encode(obj)\n          ^^^^^^^^^^^\n  File \"C:\\Users\\HP\\AppData\\Local\\Programs\\Python\\Python311\\Lib\\json\\encoder.py\", line 200, in encode\n    chunks = self.iterencode(o, _one_shot=True)\n             ^^^^^^^^^^^^^^^^^^^^^^^^^^^^^^^^^^\n  File \"C:\\Users\\HP\\AppData\\Local\\Programs\\Python\\Python311\\Lib\\json\\encoder.py\", line 258, in iterencode\n    return _iterencode(o, 0)\n           ^^^^^^^^^^^^^^^^^\n  File \"C:\\Users\\HP\\AppData\\Local\\Programs\\Python\\Python311\\Lib\\json\\encoder.py\", line 180, in default\n    raise TypeError(f'Object of type {o.__class__.__name__} '\nTypeError: Object of type TypeError is not JSON serializable\n\nDuring handling of the above exception, another exception occurred:\n\nTraceback (most recent call last):\n  File \"C:\\Users\\HP\\AppData\\Local\\Programs\\Python\\Python311\\Lib\\site-packages\\flask_socketio\\__init__.py\", line 823, in _handle_event\n    ret = handler(auth)\n          ^^^^^^^^^^^^^\nTypeError: LiveDataNamespace.on_connect() takes 1 positional argument but 2 were given\n\nDuring handling of the above exception, another exception occurred:\n\nTraceback (most recent call last):\n  File \"C:\\Users\\HP\\AppData\\Local\\Programs\\Python\\Python311\\Lib\\site-packages\\fyers_apiv3\\FyersWebsocket\\data_ws.py\", line 1508, in on_open\n    self.OnOpen()\n  File \"E:\\Github\\Stock-analyzing-website\\Back_end\\live_stock.py\", line 61, in onopen\n    fyers.holdings()\n    ^^^^^^^^^^^^^^\nAttributeError: 'FyersDataSocket' object has no attribute 'holdings'\n\nDuring handling of the above exception, another exception occurred:\n\nTraceback (most recent call last):\n  File \"C:\\Users\\HP\\AppData\\Local\\Programs\\Python\\Python311\\Lib\\site-packages\\fyers_apiv3\\FyersWebsocket\\data_ws.py\", line 1526, in connect\n    self.on_open()\n  File \"C:\\Users\\HP\\AppData\\Local\\Programs\\Python\\Python311\\Lib\\site-packages\\fyers_apiv3\\FyersWebsocket\\data_ws.py\", line 1511, in on_open\n    self.On_error(e)\n  File \"C:\\Users\\HP\\AppData\\Local\\Programs\\Python\\Python311\\Lib\\site-packages\\fyers_apiv3\\FyersWebsocket\\data_ws.py\", line 1492, in On_error\n    self.OnError(message)\n  File \"E:\\Github\\Stock-analyzing-website\\Back_end\\live_stock.py\", line 45, in onerror\n    self.emit('message', message)\n  File \"C:\\Users\\HP\\AppData\\Local\\Programs\\Python\\Python311\\Lib\\site-packages\\flask_socketio\\namespace.py\", line 31, in emit\n    return self.socketio.emit(event, data, room=room,\n           ^^^^^^^^^^^^^^^^^^^^^^^^^^^^^^^^^^^^^^^^^^\n  File \"C:\\Users\\HP\\AppData\\Local\\Programs\\Python\\Python311\\Lib\\site-packages\\flask_socketio\\__init__.py\", line 462, in emit\n    self.server.emit(event, *args, namespace=namespace, to=to,\n  File \"C:\\Users\\HP\\AppData\\Local\\Programs\\Python\\Python311\\Lib\\site-packages\\socketio\\server.py\", line 163, in emit\n    self.manager.emit(event, data, namespace, room=room,\n  File \"C:\\Users\\HP\\AppData\\Local\\Programs\\Python\\Python311\\Lib\\site-packages\\socketio\\manager.py\", line 43, in emit\n    encoded_packet = pkt.encode()\n                     ^^^^^^^^^^^^\n  File \"C:\\Users\\HP\\AppData\\Local\\Programs\\Python\\Python311\\Lib\\site-packages\\socketio\\packet.py\", line 64, in encode\n    encoded_packet += self.json.dumps(data, separators=(',', ':'))\n                      ^^^^^^^^^^^^^^^^^^^^^^^^^^^^^^^^^^^^^^^^^^^^\n  File \"C:\\Users\\HP\\AppData\\Local\\Programs\\Python\\Python311\\Lib\\json\\__init__.py\", line 238, in dumps\n    **kw).encode(obj)\n          ^^^^^^^^^^^\n  File \"C:\\Users\\HP\\AppData\\Local\\Programs\\Python\\Python311\\Lib\\json\\encoder.py\", line 200, in encode\n    chunks = self.iterencode(o, _one_shot=True)\n             ^^^^^^^^^^^^^^^^^^^^^^^^^^^^^^^^^^\n  File \"C:\\Users\\HP\\AppData\\Local\\Programs\\Python\\Python311\\Lib\\json\\encoder.py\", line 258, in iterencode\n    return _iterencode(o, 0)\n           ^^^^^^^^^^^^^^^^^\n  File \"C:\\Users\\HP\\AppData\\Local\\Programs\\Python\\Python311\\Lib\\json\\encoder.py\", line 180, in default\n    raise TypeError(f'Object of type {o.__class__.__name__} '\nTypeError: Object of type AttributeError is not JSON serializable","exception_name":"TypeError"}
{"level":"ERROR","location":"[symbol_to_hsmtoken:128] data_ws","message":"'fyToken'","timestamp":"2024-03-31 10:29:05,689+0530","service":"FyersDataSocket","exception":"Traceback (most recent call last):\n  File \"C:\\Users\\HP\\AppData\\Local\\Programs\\Python\\Python311\\Lib\\site-packages\\flask_socketio\\__init__.py\", line 823, in _handle_event\n    ret = handler(auth)\n          ^^^^^^^^^^^^^\nTypeError: LiveDataNamespace.on_connect() takes 1 positional argument but 2 were given\n\nDuring handling of the above exception, another exception occurred:\n\nTraceback (most recent call last):\n  File \"C:\\Users\\HP\\AppData\\Local\\Programs\\Python\\Python311\\Lib\\site-packages\\fyers_apiv3\\FyersWebsocket\\data_ws.py\", line 87, in symbol_to_hsmtoken\n    values[\"fyToken\"] = data[\"v\"][\"fyToken\"]\n                        ~~~~~~~~~^^^^^^^^^^^\nKeyError: 'fyToken'","exception_name":"KeyError"}
{"level":"ERROR","location":"[__symbol_conversion:1366] data_ws","message":"'NoneType' object is not subscriptable","timestamp":"2024-03-31 10:29:05,696+0530","service":"FyersDataSocket","exception":"Traceback (most recent call last):\n  File \"C:\\Users\\HP\\AppData\\Local\\Programs\\Python\\Python311\\Lib\\site-packages\\flask_socketio\\__init__.py\", line 823, in _handle_event\n    ret = handler(auth)\n          ^^^^^^^^^^^^^\nTypeError: LiveDataNamespace.on_connect() takes 1 positional argument but 2 were given\n\nDuring handling of the above exception, another exception occurred:\n\nTraceback (most recent call last):\n  File \"C:\\Users\\HP\\AppData\\Local\\Programs\\Python\\Python311\\Lib\\site-packages\\fyers_apiv3\\FyersWebsocket\\data_ws.py\", line 1334, in __symbol_conversion\n    symbol_dict.update(symbol_dict, **symbol_value[0])\n                                      ~~~~~~~~~~~~^^^\nTypeError: 'NoneType' object is not subscriptable","exception_name":"TypeError"}
{"level":"ERROR","location":"[symbol_to_hsmtoken:128] data_ws","message":"'fyToken'","timestamp":"2024-03-31 10:31:34,911+0530","service":"FyersDataSocket","exception":"Traceback (most recent call last):\n  File \"C:\\Users\\HP\\AppData\\Local\\Programs\\Python\\Python311\\Lib\\site-packages\\flask_socketio\\__init__.py\", line 823, in _handle_event\n    ret = handler(auth)\n          ^^^^^^^^^^^^^\nTypeError: LiveDataNamespace.on_connect() takes 1 positional argument but 2 were given\n\nDuring handling of the above exception, another exception occurred:\n\nTraceback (most recent call last):\n  File \"C:\\Users\\HP\\AppData\\Local\\Programs\\Python\\Python311\\Lib\\site-packages\\fyers_apiv3\\FyersWebsocket\\data_ws.py\", line 87, in symbol_to_hsmtoken\n    values[\"fyToken\"] = data[\"v\"][\"fyToken\"]\n                        ~~~~~~~~~^^^^^^^^^^^\nKeyError: 'fyToken'","exception_name":"KeyError"}
{"level":"ERROR","location":"[__symbol_conversion:1366] data_ws","message":"'NoneType' object is not subscriptable","timestamp":"2024-03-31 10:31:34,917+0530","service":"FyersDataSocket","exception":"Traceback (most recent call last):\n  File \"C:\\Users\\HP\\AppData\\Local\\Programs\\Python\\Python311\\Lib\\site-packages\\flask_socketio\\__init__.py\", line 823, in _handle_event\n    ret = handler(auth)\n          ^^^^^^^^^^^^^\nTypeError: LiveDataNamespace.on_connect() takes 1 positional argument but 2 were given\n\nDuring handling of the above exception, another exception occurred:\n\nTraceback (most recent call last):\n  File \"C:\\Users\\HP\\AppData\\Local\\Programs\\Python\\Python311\\Lib\\site-packages\\fyers_apiv3\\FyersWebsocket\\data_ws.py\", line 1334, in __symbol_conversion\n    symbol_dict.update(symbol_dict, **symbol_value[0])\n                                      ~~~~~~~~~~~~^^^\nTypeError: 'NoneType' object is not subscriptable","exception_name":"TypeError"}
{"level":"ERROR","location":"[symbol_to_hsmtoken:128] data_ws","message":"'fyToken'","timestamp":"2024-03-31 11:29:23,632+0530","service":"FyersDataSocket","exception":"Traceback (most recent call last):\n  File \"C:\\Users\\HP\\AppData\\Local\\Programs\\Python\\Python311\\Lib\\site-packages\\flask_socketio\\__init__.py\", line 823, in _handle_event\n    ret = handler(auth)\n          ^^^^^^^^^^^^^\nTypeError: LiveDataNamespace.on_connect() takes 1 positional argument but 2 were given\n\nDuring handling of the above exception, another exception occurred:\n\nTraceback (most recent call last):\n  File \"C:\\Users\\HP\\AppData\\Local\\Programs\\Python\\Python311\\Lib\\site-packages\\fyers_apiv3\\FyersWebsocket\\data_ws.py\", line 87, in symbol_to_hsmtoken\n    values[\"fyToken\"] = data[\"v\"][\"fyToken\"]\n                        ~~~~~~~~~^^^^^^^^^^^\nKeyError: 'fyToken'","exception_name":"KeyError"}
{"level":"ERROR","location":"[__symbol_conversion:1366] data_ws","message":"'NoneType' object is not subscriptable","timestamp":"2024-03-31 11:29:23,643+0530","service":"FyersDataSocket","exception":"Traceback (most recent call last):\n  File \"C:\\Users\\HP\\AppData\\Local\\Programs\\Python\\Python311\\Lib\\site-packages\\flask_socketio\\__init__.py\", line 823, in _handle_event\n    ret = handler(auth)\n          ^^^^^^^^^^^^^\nTypeError: LiveDataNamespace.on_connect() takes 1 positional argument but 2 were given\n\nDuring handling of the above exception, another exception occurred:\n\nTraceback (most recent call last):\n  File \"C:\\Users\\HP\\AppData\\Local\\Programs\\Python\\Python311\\Lib\\site-packages\\fyers_apiv3\\FyersWebsocket\\data_ws.py\", line 1334, in __symbol_conversion\n    symbol_dict.update(symbol_dict, **symbol_value[0])\n                                      ~~~~~~~~~~~~^^^\nTypeError: 'NoneType' object is not subscriptable","exception_name":"TypeError"}
{"level":"ERROR","location":"[symbol_to_hsmtoken:128] data_ws","message":"HTTPSConnectionPool(host='api-t1.fyers.in', port=443): Max retries exceeded with url: /data/quotes?symbols=NSE%3ALICI-EQ%2CNSE%3AJIOFIN-EQ (Caused by NewConnectionError('<urllib3.connection.HTTPSConnection object at 0x0000018F38167250>: Failed to establish a new connection: [Errno 11001] getaddrinfo failed'))","timestamp":"2024-03-31 22:37:16,109+0530","service":"FyersDataSocket","exception":"Traceback (most recent call last):\n  File \"C:\\Users\\HP\\AppData\\Local\\Programs\\Python\\Python311\\Lib\\site-packages\\websocket\\_app.py\", line 428, in setSock\n    dispatcher.read(self.sock.sock, read, check)\n  File \"C:\\Users\\HP\\AppData\\Local\\Programs\\Python\\Python311\\Lib\\site-packages\\websocket\\_app.py\", line 99, in read\n    if not read_callback():\n           ^^^^^^^^^^^^^^^\n  File \"C:\\Users\\HP\\AppData\\Local\\Programs\\Python\\Python311\\Lib\\site-packages\\websocket\\_app.py\", line 442, in read\n    raise e\n  File \"C:\\Users\\HP\\AppData\\Local\\Programs\\Python\\Python311\\Lib\\site-packages\\websocket\\_app.py\", line 437, in read\n    op_code, frame = self.sock.recv_data_frame(True)\n                     ^^^^^^^^^^^^^^^^^^^^^^^^^^^^^^^\n  File \"C:\\Users\\HP\\AppData\\Local\\Programs\\Python\\Python311\\Lib\\site-packages\\websocket\\_core.py\", line 406, in recv_data_frame\n    frame = self.recv_frame()\n            ^^^^^^^^^^^^^^^^^\n  File \"C:\\Users\\HP\\AppData\\Local\\Programs\\Python\\Python311\\Lib\\site-packages\\websocket\\_core.py\", line 445, in recv_frame\n    return self.frame_buffer.recv_frame()\n           ^^^^^^^^^^^^^^^^^^^^^^^^^^^^^^\n  File \"C:\\Users\\HP\\AppData\\Local\\Programs\\Python\\Python311\\Lib\\site-packages\\websocket\\_abnf.py\", line 338, in recv_frame\n    self.recv_header()\n  File \"C:\\Users\\HP\\AppData\\Local\\Programs\\Python\\Python311\\Lib\\site-packages\\websocket\\_abnf.py\", line 294, in recv_header\n    header = self.recv_strict(2)\n             ^^^^^^^^^^^^^^^^^^^\n  File \"C:\\Users\\HP\\AppData\\Local\\Programs\\Python\\Python311\\Lib\\site-packages\\websocket\\_abnf.py\", line 373, in recv_strict\n    bytes_ = self.recv(min(16384, shortage))\n             ^^^^^^^^^^^^^^^^^^^^^^^^^^^^^^^\n  File \"C:\\Users\\HP\\AppData\\Local\\Programs\\Python\\Python311\\Lib\\site-packages\\websocket\\_core.py\", line 529, in _recv\n    return recv(self.sock, bufsize)\n           ^^^^^^^^^^^^^^^^^^^^^^^^\n  File \"C:\\Users\\HP\\AppData\\Local\\Programs\\Python\\Python311\\Lib\\site-packages\\websocket\\_socket.py\", line 122, in recv\n    raise WebSocketConnectionClosedException(\nwebsocket._exceptions.WebSocketConnectionClosedException: Connection to remote host was lost.\n\nDuring handling of the above exception, another exception occurred:\n\nTraceback (most recent call last):\n  File \"C:\\Users\\HP\\AppData\\Local\\Programs\\Python\\Python311\\Lib\\site-packages\\websocket\\_app.py\", line 547, in _callback\n    callback(self, *args)\n  File \"C:\\Users\\HP\\AppData\\Local\\Programs\\Python\\Python311\\Lib\\site-packages\\fyers_apiv3\\FyersWebsocket\\data_ws.py\", line 1653, in <lambda>\n    on_error=lambda ws, msg: self.On_error(msg),\n                             ^^^^^^^^^^^^^^^^^^\n  File \"C:\\Users\\HP\\AppData\\Local\\Programs\\Python\\Python311\\Lib\\site-packages\\fyers_apiv3\\FyersWebsocket\\data_ws.py\", line 1492, in On_error\n    self.OnError(message)\n  File \"E:\\Github\\Stock-analyzing-website\\Back_end\\live_stock.py\", line 53, in onerror\n    self.emit('message', message)\n  File \"C:\\Users\\HP\\AppData\\Local\\Programs\\Python\\Python311\\Lib\\site-packages\\flask_socketio\\namespace.py\", line 31, in emit\n    return self.socketio.emit(event, data, room=room,\n           ^^^^^^^^^^^^^^^^^^^^^^^^^^^^^^^^^^^^^^^^^^\n  File \"C:\\Users\\HP\\AppData\\Local\\Programs\\Python\\Python311\\Lib\\site-packages\\flask_socketio\\__init__.py\", line 462, in emit\n    self.server.emit(event, *args, namespace=namespace, to=to,\n  File \"C:\\Users\\HP\\AppData\\Local\\Programs\\Python\\Python311\\Lib\\site-packages\\socketio\\server.py\", line 163, in emit\n    self.manager.emit(event, data, namespace, room=room,\n  File \"C:\\Users\\HP\\AppData\\Local\\Programs\\Python\\Python311\\Lib\\site-packages\\socketio\\manager.py\", line 43, in emit\n    encoded_packet = pkt.encode()\n                     ^^^^^^^^^^^^\n  File \"C:\\Users\\HP\\AppData\\Local\\Programs\\Python\\Python311\\Lib\\site-packages\\socketio\\packet.py\", line 64, in encode\n    encoded_packet += self.json.dumps(data, separators=(',', ':'))\n                      ^^^^^^^^^^^^^^^^^^^^^^^^^^^^^^^^^^^^^^^^^^^^\n  File \"C:\\Users\\HP\\AppData\\Local\\Programs\\Python\\Python311\\Lib\\json\\__init__.py\", line 238, in dumps\n    **kw).encode(obj)\n          ^^^^^^^^^^^\n  File \"C:\\Users\\HP\\AppData\\Local\\Programs\\Python\\Python311\\Lib\\json\\encoder.py\", line 200, in encode\n    chunks = self.iterencode(o, _one_shot=True)\n             ^^^^^^^^^^^^^^^^^^^^^^^^^^^^^^^^^^\n  File \"C:\\Users\\HP\\AppData\\Local\\Programs\\Python\\Python311\\Lib\\json\\encoder.py\", line 258, in iterencode\n    return _iterencode(o, 0)\n           ^^^^^^^^^^^^^^^^^\n  File \"C:\\Users\\HP\\AppData\\Local\\Programs\\Python\\Python311\\Lib\\json\\encoder.py\", line 180, in default\n    raise TypeError(f'Object of type {o.__class__.__name__} '\nTypeError: Object of type WebSocketConnectionClosedException is not JSON serializable\n\nDuring handling of the above exception, another exception occurred:\n\nTraceback (most recent call last):\n  File \"C:\\Users\\HP\\AppData\\Local\\Programs\\Python\\Python311\\Lib\\site-packages\\websocket\\_app.py\", line 501, in run_forever\n    setSock()\n  File \"C:\\Users\\HP\\AppData\\Local\\Programs\\Python\\Python311\\Lib\\site-packages\\websocket\\_app.py\", line 430, in setSock\n    handleDisconnect(e, reconnecting)\n  File \"C:\\Users\\HP\\AppData\\Local\\Programs\\Python\\Python311\\Lib\\site-packages\\websocket\\_app.py\", line 481, in handleDisconnect\n    self._callback(self.on_error, e)\n  File \"C:\\Users\\HP\\AppData\\Local\\Programs\\Python\\Python311\\Lib\\site-packages\\websocket\\_app.py\", line 552, in _callback\n    self.on_error(self, e)\n  File \"C:\\Users\\HP\\AppData\\Local\\Programs\\Python\\Python311\\Lib\\site-packages\\fyers_apiv3\\FyersWebsocket\\data_ws.py\", line 1653, in <lambda>\n    on_error=lambda ws, msg: self.On_error(msg),\n                             ^^^^^^^^^^^^^^^^^^\n  File \"C:\\Users\\HP\\AppData\\Local\\Programs\\Python\\Python311\\Lib\\site-packages\\fyers_apiv3\\FyersWebsocket\\data_ws.py\", line 1492, in On_error\n    self.OnError(message)\n  File \"E:\\Github\\Stock-analyzing-website\\Back_end\\live_stock.py\", line 53, in onerror\n    self.emit('message', message)\n  File \"C:\\Users\\HP\\AppData\\Local\\Programs\\Python\\Python311\\Lib\\site-packages\\flask_socketio\\namespace.py\", line 31, in emit\n    return self.socketio.emit(event, data, room=room,\n           ^^^^^^^^^^^^^^^^^^^^^^^^^^^^^^^^^^^^^^^^^^\n  File \"C:\\Users\\HP\\AppData\\Local\\Programs\\Python\\Python311\\Lib\\site-packages\\flask_socketio\\__init__.py\", line 462, in emit\n    self.server.emit(event, *args, namespace=namespace, to=to,\n  File \"C:\\Users\\HP\\AppData\\Local\\Programs\\Python\\Python311\\Lib\\site-packages\\socketio\\server.py\", line 163, in emit\n    self.manager.emit(event, data, namespace, room=room,\n  File \"C:\\Users\\HP\\AppData\\Local\\Programs\\Python\\Python311\\Lib\\site-packages\\socketio\\manager.py\", line 43, in emit\n    encoded_packet = pkt.encode()\n                     ^^^^^^^^^^^^\n  File \"C:\\Users\\HP\\AppData\\Local\\Programs\\Python\\Python311\\Lib\\site-packages\\socketio\\packet.py\", line 64, in encode\n    encoded_packet += self.json.dumps(data, separators=(',', ':'))\n                      ^^^^^^^^^^^^^^^^^^^^^^^^^^^^^^^^^^^^^^^^^^^^\n  File \"C:\\Users\\HP\\AppData\\Local\\Programs\\Python\\Python311\\Lib\\json\\__init__.py\", line 238, in dumps\n    **kw).encode(obj)\n          ^^^^^^^^^^^\n  File \"C:\\Users\\HP\\AppData\\Local\\Programs\\Python\\Python311\\Lib\\json\\encoder.py\", line 200, in encode\n    chunks = self.iterencode(o, _one_shot=True)\n             ^^^^^^^^^^^^^^^^^^^^^^^^^^^^^^^^^^\n  File \"C:\\Users\\HP\\AppData\\Local\\Programs\\Python\\Python311\\Lib\\json\\encoder.py\", line 258, in iterencode\n    return _iterencode(o, 0)\n           ^^^^^^^^^^^^^^^^^\n  File \"C:\\Users\\HP\\AppData\\Local\\Programs\\Python\\Python311\\Lib\\json\\encoder.py\", line 180, in default\n    raise TypeError(f'Object of type {o.__class__.__name__} '\nTypeError: Object of type TypeError is not JSON serializable\n\nDuring handling of the above exception, another exception occurred:\n\nTraceback (most recent call last):\n  File \"C:\\Users\\HP\\AppData\\Local\\Programs\\Python\\Python311\\Lib\\site-packages\\urllib3\\connection.py\", line 174, in _new_conn\n    conn = connection.create_connection(\n           ^^^^^^^^^^^^^^^^^^^^^^^^^^^^^\n  File \"C:\\Users\\HP\\AppData\\Local\\Programs\\Python\\Python311\\Lib\\site-packages\\urllib3\\util\\connection.py\", line 72, in create_connection\n    for res in socket.getaddrinfo(host, port, family, socket.SOCK_STREAM):\n               ^^^^^^^^^^^^^^^^^^^^^^^^^^^^^^^^^^^^^^^^^^^^^^^^^^^^^^^^^^\n  File \"C:\\Users\\HP\\AppData\\Local\\Programs\\Python\\Python311\\Lib\\socket.py\", line 962, in getaddrinfo\n    for res in _socket.getaddrinfo(host, port, family, type, proto, flags):\n               ^^^^^^^^^^^^^^^^^^^^^^^^^^^^^^^^^^^^^^^^^^^^^^^^^^^^^^^^^^^\nsocket.gaierror: [Errno 11001] getaddrinfo failed\n\nDuring handling of the above exception, another exception occurred:\n\nTraceback (most recent call last):\n  File \"C:\\Users\\HP\\AppData\\Local\\Programs\\Python\\Python311\\Lib\\site-packages\\urllib3\\connectionpool.py\", line 703, in urlopen\n    httplib_response = self._make_request(\n                       ^^^^^^^^^^^^^^^^^^^\n  File \"C:\\Users\\HP\\AppData\\Local\\Programs\\Python\\Python311\\Lib\\site-packages\\urllib3\\connectionpool.py\", line 386, in _make_request\n    self._validate_conn(conn)\n  File \"C:\\Users\\HP\\AppData\\Local\\Programs\\Python\\Python311\\Lib\\site-packages\\urllib3\\connectionpool.py\", line 1042, in _validate_conn\n    conn.connect()\n  File \"C:\\Users\\HP\\AppData\\Local\\Programs\\Python\\Python311\\Lib\\site-packages\\urllib3\\connection.py\", line 358, in connect\n    self.sock = conn = self._new_conn()\n                       ^^^^^^^^^^^^^^^^\n  File \"C:\\Users\\HP\\AppData\\Local\\Programs\\Python\\Python311\\Lib\\site-packages\\urllib3\\connection.py\", line 186, in _new_conn\n    raise NewConnectionError(\nurllib3.exceptions.NewConnectionError: <urllib3.connection.HTTPSConnection object at 0x0000018F38167250>: Failed to establish a new connection: [Errno 11001] getaddrinfo failed\n\nDuring handling of the above exception, another exception occurred:\n\nTraceback (most recent call last):\n  File \"C:\\Users\\HP\\AppData\\Local\\Programs\\Python\\Python311\\Lib\\site-packages\\requests\\adapters.py\", line 486, in send\n    resp = conn.urlopen(\n           ^^^^^^^^^^^^^\n  File \"C:\\Users\\HP\\AppData\\Local\\Programs\\Python\\Python311\\Lib\\site-packages\\urllib3\\connectionpool.py\", line 787, in urlopen\n    retries = retries.increment(\n              ^^^^^^^^^^^^^^^^^^\n  File \"C:\\Users\\HP\\AppData\\Local\\Programs\\Python\\Python311\\Lib\\site-packages\\urllib3\\util\\retry.py\", line 592, in increment\n    raise MaxRetryError(_pool, url, error or ResponseError(cause))\nurllib3.exceptions.MaxRetryError: HTTPSConnectionPool(host='api-t1.fyers.in', port=443): Max retries exceeded with url: /data/quotes?symbols=NSE%3ALICI-EQ%2CNSE%3AJIOFIN-EQ (Caused by NewConnectionError('<urllib3.connection.HTTPSConnection object at 0x0000018F38167250>: Failed to establish a new connection: [Errno 11001] getaddrinfo failed'))\n\nDuring handling of the above exception, another exception occurred:\n\nTraceback (most recent call last):\n  File \"C:\\Users\\HP\\AppData\\Local\\Programs\\Python\\Python311\\Lib\\site-packages\\fyers_apiv3\\FyersWebsocket\\data_ws.py\", line 65, in symbol_to_hsmtoken\n    response = requests.get(\n               ^^^^^^^^^^^^^\n  File \"C:\\Users\\HP\\AppData\\Local\\Programs\\Python\\Python311\\Lib\\site-packages\\requests\\api.py\", line 73, in get\n    return request(\"get\", url, params=params, **kwargs)\n           ^^^^^^^^^^^^^^^^^^^^^^^^^^^^^^^^^^^^^^^^^^^^\n  File \"C:\\Users\\HP\\AppData\\Local\\Programs\\Python\\Python311\\Lib\\site-packages\\requests\\api.py\", line 59, in request\n    return session.request(method=method, url=url, **kwargs)\n           ^^^^^^^^^^^^^^^^^^^^^^^^^^^^^^^^^^^^^^^^^^^^^^^^^\n  File \"C:\\Users\\HP\\AppData\\Local\\Programs\\Python\\Python311\\Lib\\site-packages\\requests\\sessions.py\", line 589, in request\n    resp = self.send(prep, **send_kwargs)\n           ^^^^^^^^^^^^^^^^^^^^^^^^^^^^^^\n  File \"C:\\Users\\HP\\AppData\\Local\\Programs\\Python\\Python311\\Lib\\site-packages\\requests\\sessions.py\", line 703, in send\n    r = adapter.send(request, **kwargs)\n        ^^^^^^^^^^^^^^^^^^^^^^^^^^^^^^^\n  File \"C:\\Users\\HP\\AppData\\Local\\Programs\\Python\\Python311\\Lib\\site-packages\\requests\\adapters.py\", line 519, in send\n    raise ConnectionError(e, request=request)\nrequests.exceptions.ConnectionError: HTTPSConnectionPool(host='api-t1.fyers.in', port=443): Max retries exceeded with url: /data/quotes?symbols=NSE%3ALICI-EQ%2CNSE%3AJIOFIN-EQ (Caused by NewConnectionError('<urllib3.connection.HTTPSConnection object at 0x0000018F38167250>: Failed to establish a new connection: [Errno 11001] getaddrinfo failed'))","exception_name":"ConnectionError"}
{"level":"ERROR","location":"[__symbol_conversion:1366] data_ws","message":"'NoneType' object is not subscriptable","timestamp":"2024-03-31 22:37:16,507+0530","service":"FyersDataSocket","exception":"Traceback (most recent call last):\n  File \"C:\\Users\\HP\\AppData\\Local\\Programs\\Python\\Python311\\Lib\\site-packages\\websocket\\_app.py\", line 428, in setSock\n    dispatcher.read(self.sock.sock, read, check)\n  File \"C:\\Users\\HP\\AppData\\Local\\Programs\\Python\\Python311\\Lib\\site-packages\\websocket\\_app.py\", line 99, in read\n    if not read_callback():\n           ^^^^^^^^^^^^^^^\n  File \"C:\\Users\\HP\\AppData\\Local\\Programs\\Python\\Python311\\Lib\\site-packages\\websocket\\_app.py\", line 442, in read\n    raise e\n  File \"C:\\Users\\HP\\AppData\\Local\\Programs\\Python\\Python311\\Lib\\site-packages\\websocket\\_app.py\", line 437, in read\n    op_code, frame = self.sock.recv_data_frame(True)\n                     ^^^^^^^^^^^^^^^^^^^^^^^^^^^^^^^\n  File \"C:\\Users\\HP\\AppData\\Local\\Programs\\Python\\Python311\\Lib\\site-packages\\websocket\\_core.py\", line 406, in recv_data_frame\n    frame = self.recv_frame()\n            ^^^^^^^^^^^^^^^^^\n  File \"C:\\Users\\HP\\AppData\\Local\\Programs\\Python\\Python311\\Lib\\site-packages\\websocket\\_core.py\", line 445, in recv_frame\n    return self.frame_buffer.recv_frame()\n           ^^^^^^^^^^^^^^^^^^^^^^^^^^^^^^\n  File \"C:\\Users\\HP\\AppData\\Local\\Programs\\Python\\Python311\\Lib\\site-packages\\websocket\\_abnf.py\", line 338, in recv_frame\n    self.recv_header()\n  File \"C:\\Users\\HP\\AppData\\Local\\Programs\\Python\\Python311\\Lib\\site-packages\\websocket\\_abnf.py\", line 294, in recv_header\n    header = self.recv_strict(2)\n             ^^^^^^^^^^^^^^^^^^^\n  File \"C:\\Users\\HP\\AppData\\Local\\Programs\\Python\\Python311\\Lib\\site-packages\\websocket\\_abnf.py\", line 373, in recv_strict\n    bytes_ = self.recv(min(16384, shortage))\n             ^^^^^^^^^^^^^^^^^^^^^^^^^^^^^^^\n  File \"C:\\Users\\HP\\AppData\\Local\\Programs\\Python\\Python311\\Lib\\site-packages\\websocket\\_core.py\", line 529, in _recv\n    return recv(self.sock, bufsize)\n           ^^^^^^^^^^^^^^^^^^^^^^^^\n  File \"C:\\Users\\HP\\AppData\\Local\\Programs\\Python\\Python311\\Lib\\site-packages\\websocket\\_socket.py\", line 122, in recv\n    raise WebSocketConnectionClosedException(\nwebsocket._exceptions.WebSocketConnectionClosedException: Connection to remote host was lost.\n\nDuring handling of the above exception, another exception occurred:\n\nTraceback (most recent call last):\n  File \"C:\\Users\\HP\\AppData\\Local\\Programs\\Python\\Python311\\Lib\\site-packages\\websocket\\_app.py\", line 547, in _callback\n    callback(self, *args)\n  File \"C:\\Users\\HP\\AppData\\Local\\Programs\\Python\\Python311\\Lib\\site-packages\\fyers_apiv3\\FyersWebsocket\\data_ws.py\", line 1653, in <lambda>\n    on_error=lambda ws, msg: self.On_error(msg),\n                             ^^^^^^^^^^^^^^^^^^\n  File \"C:\\Users\\HP\\AppData\\Local\\Programs\\Python\\Python311\\Lib\\site-packages\\fyers_apiv3\\FyersWebsocket\\data_ws.py\", line 1492, in On_error\n    self.OnError(message)\n  File \"E:\\Github\\Stock-analyzing-website\\Back_end\\live_stock.py\", line 53, in onerror\n    self.emit('message', message)\n  File \"C:\\Users\\HP\\AppData\\Local\\Programs\\Python\\Python311\\Lib\\site-packages\\flask_socketio\\namespace.py\", line 31, in emit\n    return self.socketio.emit(event, data, room=room,\n           ^^^^^^^^^^^^^^^^^^^^^^^^^^^^^^^^^^^^^^^^^^\n  File \"C:\\Users\\HP\\AppData\\Local\\Programs\\Python\\Python311\\Lib\\site-packages\\flask_socketio\\__init__.py\", line 462, in emit\n    self.server.emit(event, *args, namespace=namespace, to=to,\n  File \"C:\\Users\\HP\\AppData\\Local\\Programs\\Python\\Python311\\Lib\\site-packages\\socketio\\server.py\", line 163, in emit\n    self.manager.emit(event, data, namespace, room=room,\n  File \"C:\\Users\\HP\\AppData\\Local\\Programs\\Python\\Python311\\Lib\\site-packages\\socketio\\manager.py\", line 43, in emit\n    encoded_packet = pkt.encode()\n                     ^^^^^^^^^^^^\n  File \"C:\\Users\\HP\\AppData\\Local\\Programs\\Python\\Python311\\Lib\\site-packages\\socketio\\packet.py\", line 64, in encode\n    encoded_packet += self.json.dumps(data, separators=(',', ':'))\n                      ^^^^^^^^^^^^^^^^^^^^^^^^^^^^^^^^^^^^^^^^^^^^\n  File \"C:\\Users\\HP\\AppData\\Local\\Programs\\Python\\Python311\\Lib\\json\\__init__.py\", line 238, in dumps\n    **kw).encode(obj)\n          ^^^^^^^^^^^\n  File \"C:\\Users\\HP\\AppData\\Local\\Programs\\Python\\Python311\\Lib\\json\\encoder.py\", line 200, in encode\n    chunks = self.iterencode(o, _one_shot=True)\n             ^^^^^^^^^^^^^^^^^^^^^^^^^^^^^^^^^^\n  File \"C:\\Users\\HP\\AppData\\Local\\Programs\\Python\\Python311\\Lib\\json\\encoder.py\", line 258, in iterencode\n    return _iterencode(o, 0)\n           ^^^^^^^^^^^^^^^^^\n  File \"C:\\Users\\HP\\AppData\\Local\\Programs\\Python\\Python311\\Lib\\json\\encoder.py\", line 180, in default\n    raise TypeError(f'Object of type {o.__class__.__name__} '\nTypeError: Object of type WebSocketConnectionClosedException is not JSON serializable\n\nDuring handling of the above exception, another exception occurred:\n\nTraceback (most recent call last):\n  File \"C:\\Users\\HP\\AppData\\Local\\Programs\\Python\\Python311\\Lib\\site-packages\\websocket\\_app.py\", line 501, in run_forever\n    setSock()\n  File \"C:\\Users\\HP\\AppData\\Local\\Programs\\Python\\Python311\\Lib\\site-packages\\websocket\\_app.py\", line 430, in setSock\n    handleDisconnect(e, reconnecting)\n  File \"C:\\Users\\HP\\AppData\\Local\\Programs\\Python\\Python311\\Lib\\site-packages\\websocket\\_app.py\", line 481, in handleDisconnect\n    self._callback(self.on_error, e)\n  File \"C:\\Users\\HP\\AppData\\Local\\Programs\\Python\\Python311\\Lib\\site-packages\\websocket\\_app.py\", line 552, in _callback\n    self.on_error(self, e)\n  File \"C:\\Users\\HP\\AppData\\Local\\Programs\\Python\\Python311\\Lib\\site-packages\\fyers_apiv3\\FyersWebsocket\\data_ws.py\", line 1653, in <lambda>\n    on_error=lambda ws, msg: self.On_error(msg),\n                             ^^^^^^^^^^^^^^^^^^\n  File \"C:\\Users\\HP\\AppData\\Local\\Programs\\Python\\Python311\\Lib\\site-packages\\fyers_apiv3\\FyersWebsocket\\data_ws.py\", line 1492, in On_error\n    self.OnError(message)\n  File \"E:\\Github\\Stock-analyzing-website\\Back_end\\live_stock.py\", line 53, in onerror\n    self.emit('message', message)\n  File \"C:\\Users\\HP\\AppData\\Local\\Programs\\Python\\Python311\\Lib\\site-packages\\flask_socketio\\namespace.py\", line 31, in emit\n    return self.socketio.emit(event, data, room=room,\n           ^^^^^^^^^^^^^^^^^^^^^^^^^^^^^^^^^^^^^^^^^^\n  File \"C:\\Users\\HP\\AppData\\Local\\Programs\\Python\\Python311\\Lib\\site-packages\\flask_socketio\\__init__.py\", line 462, in emit\n    self.server.emit(event, *args, namespace=namespace, to=to,\n  File \"C:\\Users\\HP\\AppData\\Local\\Programs\\Python\\Python311\\Lib\\site-packages\\socketio\\server.py\", line 163, in emit\n    self.manager.emit(event, data, namespace, room=room,\n  File \"C:\\Users\\HP\\AppData\\Local\\Programs\\Python\\Python311\\Lib\\site-packages\\socketio\\manager.py\", line 43, in emit\n    encoded_packet = pkt.encode()\n                     ^^^^^^^^^^^^\n  File \"C:\\Users\\HP\\AppData\\Local\\Programs\\Python\\Python311\\Lib\\site-packages\\socketio\\packet.py\", line 64, in encode\n    encoded_packet += self.json.dumps(data, separators=(',', ':'))\n                      ^^^^^^^^^^^^^^^^^^^^^^^^^^^^^^^^^^^^^^^^^^^^\n  File \"C:\\Users\\HP\\AppData\\Local\\Programs\\Python\\Python311\\Lib\\json\\__init__.py\", line 238, in dumps\n    **kw).encode(obj)\n          ^^^^^^^^^^^\n  File \"C:\\Users\\HP\\AppData\\Local\\Programs\\Python\\Python311\\Lib\\json\\encoder.py\", line 200, in encode\n    chunks = self.iterencode(o, _one_shot=True)\n             ^^^^^^^^^^^^^^^^^^^^^^^^^^^^^^^^^^\n  File \"C:\\Users\\HP\\AppData\\Local\\Programs\\Python\\Python311\\Lib\\json\\encoder.py\", line 258, in iterencode\n    return _iterencode(o, 0)\n           ^^^^^^^^^^^^^^^^^\n  File \"C:\\Users\\HP\\AppData\\Local\\Programs\\Python\\Python311\\Lib\\json\\encoder.py\", line 180, in default\n    raise TypeError(f'Object of type {o.__class__.__name__} '\nTypeError: Object of type TypeError is not JSON serializable\n\nDuring handling of the above exception, another exception occurred:\n\nTraceback (most recent call last):\n  File \"C:\\Users\\HP\\AppData\\Local\\Programs\\Python\\Python311\\Lib\\site-packages\\fyers_apiv3\\FyersWebsocket\\data_ws.py\", line 1334, in __symbol_conversion\n    symbol_dict.update(symbol_dict, **symbol_value[0])\n                                      ~~~~~~~~~~~~^^^\nTypeError: 'NoneType' object is not subscriptable","exception_name":"TypeError"}
{"level":"ERROR","location":"[symbol_to_hsmtoken:128] data_ws","message":"'fyToken'","timestamp":"2024-04-12 10:54:18,827+0530","service":"FyersDataSocket","exception":"Traceback (most recent call last):\n  File \"C:\\Users\\HP\\AppData\\Local\\Programs\\Python\\Python311\\Lib\\site-packages\\flask_socketio\\__init__.py\", line 823, in _handle_event\n    ret = handler(auth)\n          ^^^^^^^^^^^^^\nTypeError: LiveDataNamespace.on_connect() takes 1 positional argument but 2 were given\n\nDuring handling of the above exception, another exception occurred:\n\nTraceback (most recent call last):\n  File \"C:\\Users\\HP\\AppData\\Local\\Programs\\Python\\Python311\\Lib\\site-packages\\fyers_apiv3\\FyersWebsocket\\data_ws.py\", line 87, in symbol_to_hsmtoken\n    values[\"fyToken\"] = data[\"v\"][\"fyToken\"]\n                        ~~~~~~~~~^^^^^^^^^^^\nKeyError: 'fyToken'","exception_name":"KeyError"}
{"level":"ERROR","location":"[__symbol_conversion:1366] data_ws","message":"'NoneType' object is not subscriptable","timestamp":"2024-04-12 10:54:18,841+0530","service":"FyersDataSocket","exception":"Traceback (most recent call last):\n  File \"C:\\Users\\HP\\AppData\\Local\\Programs\\Python\\Python311\\Lib\\site-packages\\flask_socketio\\__init__.py\", line 823, in _handle_event\n    ret = handler(auth)\n          ^^^^^^^^^^^^^\nTypeError: LiveDataNamespace.on_connect() takes 1 positional argument but 2 were given\n\nDuring handling of the above exception, another exception occurred:\n\nTraceback (most recent call last):\n  File \"C:\\Users\\HP\\AppData\\Local\\Programs\\Python\\Python311\\Lib\\site-packages\\fyers_apiv3\\FyersWebsocket\\data_ws.py\", line 1334, in __symbol_conversion\n    symbol_dict.update(symbol_dict, **symbol_value[0])\n                                      ~~~~~~~~~~~~^^^\nTypeError: 'NoneType' object is not subscriptable","exception_name":"TypeError"}
{"level":"ERROR","location":"[symbol_to_hsmtoken:128] data_ws","message":"'fyToken'","timestamp":"2024-04-12 10:55:20,196+0530","service":"FyersDataSocket","exception":"Traceback (most recent call last):\n  File \"C:\\Users\\HP\\AppData\\Local\\Programs\\Python\\Python311\\Lib\\site-packages\\flask_socketio\\__init__.py\", line 823, in _handle_event\n    ret = handler(auth)\n          ^^^^^^^^^^^^^\nTypeError: LiveDataNamespace.on_connect() takes 1 positional argument but 2 were given\n\nDuring handling of the above exception, another exception occurred:\n\nTraceback (most recent call last):\n  File \"C:\\Users\\HP\\AppData\\Local\\Programs\\Python\\Python311\\Lib\\site-packages\\fyers_apiv3\\FyersWebsocket\\data_ws.py\", line 87, in symbol_to_hsmtoken\n    values[\"fyToken\"] = data[\"v\"][\"fyToken\"]\n                        ~~~~~~~~~^^^^^^^^^^^\nKeyError: 'fyToken'","exception_name":"KeyError"}
{"level":"ERROR","location":"[__symbol_conversion:1366] data_ws","message":"'NoneType' object is not subscriptable","timestamp":"2024-04-12 10:55:20,199+0530","service":"FyersDataSocket","exception":"Traceback (most recent call last):\n  File \"C:\\Users\\HP\\AppData\\Local\\Programs\\Python\\Python311\\Lib\\site-packages\\flask_socketio\\__init__.py\", line 823, in _handle_event\n    ret = handler(auth)\n          ^^^^^^^^^^^^^\nTypeError: LiveDataNamespace.on_connect() takes 1 positional argument but 2 were given\n\nDuring handling of the above exception, another exception occurred:\n\nTraceback (most recent call last):\n  File \"C:\\Users\\HP\\AppData\\Local\\Programs\\Python\\Python311\\Lib\\site-packages\\fyers_apiv3\\FyersWebsocket\\data_ws.py\", line 1334, in __symbol_conversion\n    symbol_dict.update(symbol_dict, **symbol_value[0])\n                                      ~~~~~~~~~~~~^^^\nTypeError: 'NoneType' object is not subscriptable","exception_name":"TypeError"}
{"level":"ERROR","location":"[symbol_to_hsmtoken:128] data_ws","message":"'fyToken'","timestamp":"2024-04-12 10:55:48,239+0530","service":"FyersDataSocket","exception":"Traceback (most recent call last):\n  File \"C:\\Users\\HP\\AppData\\Local\\Programs\\Python\\Python311\\Lib\\site-packages\\flask_socketio\\__init__.py\", line 823, in _handle_event\n    ret = handler(auth)\n          ^^^^^^^^^^^^^\nTypeError: LiveDataNamespace.on_connect() takes 1 positional argument but 2 were given\n\nDuring handling of the above exception, another exception occurred:\n\nTraceback (most recent call last):\n  File \"C:\\Users\\HP\\AppData\\Local\\Programs\\Python\\Python311\\Lib\\site-packages\\fyers_apiv3\\FyersWebsocket\\data_ws.py\", line 87, in symbol_to_hsmtoken\n    values[\"fyToken\"] = data[\"v\"][\"fyToken\"]\n                        ~~~~~~~~~^^^^^^^^^^^\nKeyError: 'fyToken'","exception_name":"KeyError"}
{"level":"ERROR","location":"[__symbol_conversion:1366] data_ws","message":"'NoneType' object is not subscriptable","timestamp":"2024-04-12 10:55:48,240+0530","service":"FyersDataSocket","exception":"Traceback (most recent call last):\n  File \"C:\\Users\\HP\\AppData\\Local\\Programs\\Python\\Python311\\Lib\\site-packages\\flask_socketio\\__init__.py\", line 823, in _handle_event\n    ret = handler(auth)\n          ^^^^^^^^^^^^^\nTypeError: LiveDataNamespace.on_connect() takes 1 positional argument but 2 were given\n\nDuring handling of the above exception, another exception occurred:\n\nTraceback (most recent call last):\n  File \"C:\\Users\\HP\\AppData\\Local\\Programs\\Python\\Python311\\Lib\\site-packages\\fyers_apiv3\\FyersWebsocket\\data_ws.py\", line 1334, in __symbol_conversion\n    symbol_dict.update(symbol_dict, **symbol_value[0])\n                                      ~~~~~~~~~~~~^^^\nTypeError: 'NoneType' object is not subscriptable","exception_name":"TypeError"}
{"level":"ERROR","location":"[symbol_to_hsmtoken:128] data_ws","message":"'fyToken'","timestamp":"2024-04-12 10:56:46,764+0530","service":"FyersDataSocket","exception":"Traceback (most recent call last):\n  File \"C:\\Users\\HP\\AppData\\Local\\Programs\\Python\\Python311\\Lib\\site-packages\\flask_socketio\\__init__.py\", line 823, in _handle_event\n    ret = handler(auth)\n          ^^^^^^^^^^^^^\nTypeError: LiveDataNamespace.on_connect() takes 1 positional argument but 2 were given\n\nDuring handling of the above exception, another exception occurred:\n\nTraceback (most recent call last):\n  File \"C:\\Users\\HP\\AppData\\Local\\Programs\\Python\\Python311\\Lib\\site-packages\\fyers_apiv3\\FyersWebsocket\\data_ws.py\", line 87, in symbol_to_hsmtoken\n    values[\"fyToken\"] = data[\"v\"][\"fyToken\"]\n                        ~~~~~~~~~^^^^^^^^^^^\nKeyError: 'fyToken'","exception_name":"KeyError"}
{"level":"ERROR","location":"[__symbol_conversion:1366] data_ws","message":"'NoneType' object is not subscriptable","timestamp":"2024-04-12 10:56:46,767+0530","service":"FyersDataSocket","exception":"Traceback (most recent call last):\n  File \"C:\\Users\\HP\\AppData\\Local\\Programs\\Python\\Python311\\Lib\\site-packages\\flask_socketio\\__init__.py\", line 823, in _handle_event\n    ret = handler(auth)\n          ^^^^^^^^^^^^^\nTypeError: LiveDataNamespace.on_connect() takes 1 positional argument but 2 were given\n\nDuring handling of the above exception, another exception occurred:\n\nTraceback (most recent call last):\n  File \"C:\\Users\\HP\\AppData\\Local\\Programs\\Python\\Python311\\Lib\\site-packages\\fyers_apiv3\\FyersWebsocket\\data_ws.py\", line 1334, in __symbol_conversion\n    symbol_dict.update(symbol_dict, **symbol_value[0])\n                                      ~~~~~~~~~~~~^^^\nTypeError: 'NoneType' object is not subscriptable","exception_name":"TypeError"}
{"level":"ERROR","location":"[symbol_to_hsmtoken:128] data_ws","message":"'fyToken'","timestamp":"2024-04-12 10:57:34,196+0530","service":"FyersDataSocket","exception":"Traceback (most recent call last):\n  File \"C:\\Users\\HP\\AppData\\Local\\Programs\\Python\\Python311\\Lib\\site-packages\\flask_socketio\\__init__.py\", line 823, in _handle_event\n    ret = handler(auth)\n          ^^^^^^^^^^^^^\nTypeError: LiveDataNamespace.on_connect() takes 1 positional argument but 2 were given\n\nDuring handling of the above exception, another exception occurred:\n\nTraceback (most recent call last):\n  File \"C:\\Users\\HP\\AppData\\Local\\Programs\\Python\\Python311\\Lib\\site-packages\\fyers_apiv3\\FyersWebsocket\\data_ws.py\", line 87, in symbol_to_hsmtoken\n    values[\"fyToken\"] = data[\"v\"][\"fyToken\"]\n                        ~~~~~~~~~^^^^^^^^^^^\nKeyError: 'fyToken'","exception_name":"KeyError"}
{"level":"ERROR","location":"[__symbol_conversion:1366] data_ws","message":"'NoneType' object is not subscriptable","timestamp":"2024-04-12 10:57:34,201+0530","service":"FyersDataSocket","exception":"Traceback (most recent call last):\n  File \"C:\\Users\\HP\\AppData\\Local\\Programs\\Python\\Python311\\Lib\\site-packages\\flask_socketio\\__init__.py\", line 823, in _handle_event\n    ret = handler(auth)\n          ^^^^^^^^^^^^^\nTypeError: LiveDataNamespace.on_connect() takes 1 positional argument but 2 were given\n\nDuring handling of the above exception, another exception occurred:\n\nTraceback (most recent call last):\n  File \"C:\\Users\\HP\\AppData\\Local\\Programs\\Python\\Python311\\Lib\\site-packages\\fyers_apiv3\\FyersWebsocket\\data_ws.py\", line 1334, in __symbol_conversion\n    symbol_dict.update(symbol_dict, **symbol_value[0])\n                                      ~~~~~~~~~~~~^^^\nTypeError: 'NoneType' object is not subscriptable","exception_name":"TypeError"}
{"level":"ERROR","location":"[__datafeed_resp:1262] data_ws","message":"'sf|nse_cm|17388'","timestamp":"2024-04-12 11:11:32,541+0530","service":"FyersDataSocket","exception":"Traceback (most recent call last):\n  File \"C:\\Users\\HP\\AppData\\Local\\Programs\\Python\\Python311\\Lib\\site-packages\\fyers_apiv3\\FyersWebsocket\\data_ws.py\", line 1158, in __datafeed_resp\n    self.resp[topic_name][\"symbol\"] = self.symbol_token[topic_name]\n                                      ~~~~~~~~~~~~~~~~~^^^^^^^^^^^^\nKeyError: 'sf|nse_cm|17388'","exception_name":"KeyError"}
{"level":"ERROR","location":"[__datafeed_resp:1262] data_ws","message":"'sf|nse_cm|9480'","timestamp":"2024-04-12 11:15:07,416+0530","service":"FyersDataSocket","exception":"Traceback (most recent call last):\n  File \"C:\\Users\\HP\\AppData\\Local\\Programs\\Python\\Python311\\Lib\\site-packages\\fyers_apiv3\\FyersWebsocket\\data_ws.py\", line 1158, in __datafeed_resp\n    self.resp[topic_name][\"symbol\"] = self.symbol_token[topic_name]\n                                      ~~~~~~~~~~~~~~~~~^^^^^^^^^^^^\nKeyError: 'sf|nse_cm|9480'","exception_name":"KeyError"}
{"level":"ERROR","location":"[symbol_to_hsmtoken:128] data_ws","message":"'fyToken'","timestamp":"2024-04-12 11:17:59,976+0530","service":"FyersDataSocket","exception":"Traceback (most recent call last):\n  File \"C:\\Users\\HP\\AppData\\Local\\Programs\\Python\\Python311\\Lib\\site-packages\\flask_socketio\\__init__.py\", line 823, in _handle_event\n    ret = handler(auth)\n          ^^^^^^^^^^^^^\nTypeError: LiveDataNamespace.on_connect() takes 1 positional argument but 2 were given\n\nDuring handling of the above exception, another exception occurred:\n\nTraceback (most recent call last):\n  File \"C:\\Users\\HP\\AppData\\Local\\Programs\\Python\\Python311\\Lib\\site-packages\\fyers_apiv3\\FyersWebsocket\\data_ws.py\", line 87, in symbol_to_hsmtoken\n    values[\"fyToken\"] = data[\"v\"][\"fyToken\"]\n                        ~~~~~~~~~^^^^^^^^^^^\nKeyError: 'fyToken'","exception_name":"KeyError"}
{"level":"ERROR","location":"[__symbol_conversion:1366] data_ws","message":"'NoneType' object is not subscriptable","timestamp":"2024-04-12 11:17:59,977+0530","service":"FyersDataSocket","exception":"Traceback (most recent call last):\n  File \"C:\\Users\\HP\\AppData\\Local\\Programs\\Python\\Python311\\Lib\\site-packages\\flask_socketio\\__init__.py\", line 823, in _handle_event\n    ret = handler(auth)\n          ^^^^^^^^^^^^^\nTypeError: LiveDataNamespace.on_connect() takes 1 positional argument but 2 were given\n\nDuring handling of the above exception, another exception occurred:\n\nTraceback (most recent call last):\n  File \"C:\\Users\\HP\\AppData\\Local\\Programs\\Python\\Python311\\Lib\\site-packages\\fyers_apiv3\\FyersWebsocket\\data_ws.py\", line 1334, in __symbol_conversion\n    symbol_dict.update(symbol_dict, **symbol_value[0])\n                                      ~~~~~~~~~~~~^^^\nTypeError: 'NoneType' object is not subscriptable","exception_name":"TypeError"}
{"level":"ERROR","location":"[__datafeed_resp:1262] data_ws","message":"'sf|nse_cm|18143'","timestamp":"2024-04-12 11:18:35,470+0530","service":"FyersDataSocket","exception":"Traceback (most recent call last):\n  File \"C:\\Users\\HP\\AppData\\Local\\Programs\\Python\\Python311\\Lib\\site-packages\\fyers_apiv3\\FyersWebsocket\\data_ws.py\", line 1158, in __datafeed_resp\n    self.resp[topic_name][\"symbol\"] = self.symbol_token[topic_name]\n                                      ~~~~~~~~~~~~~~~~~^^^^^^^^^^^^\nKeyError: 'sf|nse_cm|18143'","exception_name":"KeyError"}
{"level":"ERROR","location":"[symbol_to_hsmtoken:128] data_ws","message":"'fyToken'","timestamp":"2024-04-12 11:19:55,653+0530","service":"FyersDataSocket","exception":"Traceback (most recent call last):\n  File \"C:\\Users\\HP\\AppData\\Local\\Programs\\Python\\Python311\\Lib\\site-packages\\flask_socketio\\__init__.py\", line 823, in _handle_event\n    ret = handler(auth)\n          ^^^^^^^^^^^^^\nTypeError: LiveDataNamespace.on_connect() takes 1 positional argument but 2 were given\n\nDuring handling of the above exception, another exception occurred:\n\nTraceback (most recent call last):\n  File \"C:\\Users\\HP\\AppData\\Local\\Programs\\Python\\Python311\\Lib\\site-packages\\fyers_apiv3\\FyersWebsocket\\data_ws.py\", line 87, in symbol_to_hsmtoken\n    values[\"fyToken\"] = data[\"v\"][\"fyToken\"]\n                        ~~~~~~~~~^^^^^^^^^^^\nKeyError: 'fyToken'","exception_name":"KeyError"}
{"level":"ERROR","location":"[__symbol_conversion:1366] data_ws","message":"'NoneType' object is not subscriptable","timestamp":"2024-04-12 11:19:55,653+0530","service":"FyersDataSocket","exception":"Traceback (most recent call last):\n  File \"C:\\Users\\HP\\AppData\\Local\\Programs\\Python\\Python311\\Lib\\site-packages\\flask_socketio\\__init__.py\", line 823, in _handle_event\n    ret = handler(auth)\n          ^^^^^^^^^^^^^\nTypeError: LiveDataNamespace.on_connect() takes 1 positional argument but 2 were given\n\nDuring handling of the above exception, another exception occurred:\n\nTraceback (most recent call last):\n  File \"C:\\Users\\HP\\AppData\\Local\\Programs\\Python\\Python311\\Lib\\site-packages\\fyers_apiv3\\FyersWebsocket\\data_ws.py\", line 1334, in __symbol_conversion\n    symbol_dict.update(symbol_dict, **symbol_value[0])\n                                      ~~~~~~~~~~~~^^^\nTypeError: 'NoneType' object is not subscriptable","exception_name":"TypeError"}
{"level":"ERROR","location":"[symbol_to_hsmtoken:128] data_ws","message":"'fyToken'","timestamp":"2024-04-12 11:19:55,690+0530","service":"FyersDataSocket","exception":"Traceback (most recent call last):\n  File \"C:\\Users\\HP\\AppData\\Local\\Programs\\Python\\Python311\\Lib\\site-packages\\flask_socketio\\__init__.py\", line 823, in _handle_event\n    ret = handler(auth)\n          ^^^^^^^^^^^^^\nTypeError: LiveDataNamespace.on_connect() takes 1 positional argument but 2 were given\n\nDuring handling of the above exception, another exception occurred:\n\nTraceback (most recent call last):\n  File \"C:\\Users\\HP\\AppData\\Local\\Programs\\Python\\Python311\\Lib\\site-packages\\fyers_apiv3\\FyersWebsocket\\data_ws.py\", line 87, in symbol_to_hsmtoken\n    values[\"fyToken\"] = data[\"v\"][\"fyToken\"]\n                        ~~~~~~~~~^^^^^^^^^^^\nKeyError: 'fyToken'","exception_name":"KeyError"}
{"level":"ERROR","location":"[__symbol_conversion:1366] data_ws","message":"'NoneType' object is not subscriptable","timestamp":"2024-04-12 11:19:55,691+0530","service":"FyersDataSocket","exception":"Traceback (most recent call last):\n  File \"C:\\Users\\HP\\AppData\\Local\\Programs\\Python\\Python311\\Lib\\site-packages\\flask_socketio\\__init__.py\", line 823, in _handle_event\n    ret = handler(auth)\n          ^^^^^^^^^^^^^\nTypeError: LiveDataNamespace.on_connect() takes 1 positional argument but 2 were given\n\nDuring handling of the above exception, another exception occurred:\n\nTraceback (most recent call last):\n  File \"C:\\Users\\HP\\AppData\\Local\\Programs\\Python\\Python311\\Lib\\site-packages\\fyers_apiv3\\FyersWebsocket\\data_ws.py\", line 1334, in __symbol_conversion\n    symbol_dict.update(symbol_dict, **symbol_value[0])\n                                      ~~~~~~~~~~~~^^^\nTypeError: 'NoneType' object is not subscriptable","exception_name":"TypeError"}
{"level":"ERROR","location":"[unsubscribe:1756] data_ws","message":"'NoneType' object has no attribute 'keys'","timestamp":"2024-04-12 11:19:55,692+0530","service":"FyersDataSocket","exception":"Traceback (most recent call last):\n  File \"C:\\Users\\HP\\AppData\\Local\\Programs\\Python\\Python311\\Lib\\site-packages\\flask_socketio\\__init__.py\", line 823, in _handle_event\n    ret = handler(auth)\n          ^^^^^^^^^^^^^\nTypeError: LiveDataNamespace.on_connect() takes 1 positional argument but 2 were given\n\nDuring handling of the above exception, another exception occurred:\n\nTraceback (most recent call last):\n  File \"C:\\Users\\HP\\AppData\\Local\\Programs\\Python\\Python311\\Lib\\site-packages\\fyers_apiv3\\FyersWebsocket\\data_ws.py\", line 1731, in unsubscribe\n    self.unsub_symbol = list(self.channel_symbol.keys())\n                             ^^^^^^^^^^^^^^^^^^^^^^^^\nAttributeError: 'NoneType' object has no attribute 'keys'","exception_name":"AttributeError"}
{"level":"ERROR","location":"[symbol_to_hsmtoken:128] data_ws","message":"'fyToken'","timestamp":"2024-04-12 11:19:55,952+0530","service":"FyersDataSocket","exception":"Traceback (most recent call last):\n  File \"C:\\Users\\HP\\AppData\\Local\\Programs\\Python\\Python311\\Lib\\site-packages\\flask_socketio\\__init__.py\", line 823, in _handle_event\n    ret = handler(auth)\n          ^^^^^^^^^^^^^\nTypeError: LiveDataNamespace.on_connect() takes 1 positional argument but 2 were given\n\nDuring handling of the above exception, another exception occurred:\n\nTraceback (most recent call last):\n  File \"C:\\Users\\HP\\AppData\\Local\\Programs\\Python\\Python311\\Lib\\site-packages\\fyers_apiv3\\FyersWebsocket\\data_ws.py\", line 87, in symbol_to_hsmtoken\n    values[\"fyToken\"] = data[\"v\"][\"fyToken\"]\n                        ~~~~~~~~~^^^^^^^^^^^\nKeyError: 'fyToken'","exception_name":"KeyError"}
{"level":"ERROR","location":"[__symbol_conversion:1366] data_ws","message":"'NoneType' object is not subscriptable","timestamp":"2024-04-12 11:19:55,953+0530","service":"FyersDataSocket","exception":"Traceback (most recent call last):\n  File \"C:\\Users\\HP\\AppData\\Local\\Programs\\Python\\Python311\\Lib\\site-packages\\flask_socketio\\__init__.py\", line 823, in _handle_event\n    ret = handler(auth)\n          ^^^^^^^^^^^^^\nTypeError: LiveDataNamespace.on_connect() takes 1 positional argument but 2 were given\n\nDuring handling of the above exception, another exception occurred:\n\nTraceback (most recent call last):\n  File \"C:\\Users\\HP\\AppData\\Local\\Programs\\Python\\Python311\\Lib\\site-packages\\fyers_apiv3\\FyersWebsocket\\data_ws.py\", line 1334, in __symbol_conversion\n    symbol_dict.update(symbol_dict, **symbol_value[0])\n                                      ~~~~~~~~~~~~^^^\nTypeError: 'NoneType' object is not subscriptable","exception_name":"TypeError"}
{"level":"ERROR","location":"[symbol_to_hsmtoken:128] data_ws","message":"'fyToken'","timestamp":"2024-04-12 11:19:57,969+0530","service":"FyersDataSocket","exception":"Traceback (most recent call last):\n  File \"C:\\Users\\HP\\AppData\\Local\\Programs\\Python\\Python311\\Lib\\site-packages\\flask_socketio\\__init__.py\", line 823, in _handle_event\n    ret = handler(auth)\n          ^^^^^^^^^^^^^\nTypeError: LiveDataNamespace.on_connect() takes 1 positional argument but 2 were given\n\nDuring handling of the above exception, another exception occurred:\n\nTraceback (most recent call last):\n  File \"C:\\Users\\HP\\AppData\\Local\\Programs\\Python\\Python311\\Lib\\site-packages\\fyers_apiv3\\FyersWebsocket\\data_ws.py\", line 87, in symbol_to_hsmtoken\n    values[\"fyToken\"] = data[\"v\"][\"fyToken\"]\n                        ~~~~~~~~~^^^^^^^^^^^\nKeyError: 'fyToken'","exception_name":"KeyError"}
{"level":"ERROR","location":"[__symbol_conversion:1366] data_ws","message":"'NoneType' object is not subscriptable","timestamp":"2024-04-12 11:19:57,973+0530","service":"FyersDataSocket","exception":"Traceback (most recent call last):\n  File \"C:\\Users\\HP\\AppData\\Local\\Programs\\Python\\Python311\\Lib\\site-packages\\flask_socketio\\__init__.py\", line 823, in _handle_event\n    ret = handler(auth)\n          ^^^^^^^^^^^^^\nTypeError: LiveDataNamespace.on_connect() takes 1 positional argument but 2 were given\n\nDuring handling of the above exception, another exception occurred:\n\nTraceback (most recent call last):\n  File \"C:\\Users\\HP\\AppData\\Local\\Programs\\Python\\Python311\\Lib\\site-packages\\fyers_apiv3\\FyersWebsocket\\data_ws.py\", line 1334, in __symbol_conversion\n    symbol_dict.update(symbol_dict, **symbol_value[0])\n                                      ~~~~~~~~~~~~^^^\nTypeError: 'NoneType' object is not subscriptable","exception_name":"TypeError"}
{"level":"ERROR","location":"[symbol_to_hsmtoken:128] data_ws","message":"'fyToken'","timestamp":"2024-04-12 11:19:58,245+0530","service":"FyersDataSocket","exception":"Traceback (most recent call last):\n  File \"C:\\Users\\HP\\AppData\\Local\\Programs\\Python\\Python311\\Lib\\site-packages\\flask_socketio\\__init__.py\", line 823, in _handle_event\n    ret = handler(auth)\n          ^^^^^^^^^^^^^\nTypeError: LiveDataNamespace.on_connect() takes 1 positional argument but 2 were given\n\nDuring handling of the above exception, another exception occurred:\n\nTraceback (most recent call last):\n  File \"C:\\Users\\HP\\AppData\\Local\\Programs\\Python\\Python311\\Lib\\site-packages\\fyers_apiv3\\FyersWebsocket\\data_ws.py\", line 87, in symbol_to_hsmtoken\n    values[\"fyToken\"] = data[\"v\"][\"fyToken\"]\n                        ~~~~~~~~~^^^^^^^^^^^\nKeyError: 'fyToken'","exception_name":"KeyError"}
{"level":"ERROR","location":"[__symbol_conversion:1366] data_ws","message":"'NoneType' object is not subscriptable","timestamp":"2024-04-12 11:19:58,246+0530","service":"FyersDataSocket","exception":"Traceback (most recent call last):\n  File \"C:\\Users\\HP\\AppData\\Local\\Programs\\Python\\Python311\\Lib\\site-packages\\flask_socketio\\__init__.py\", line 823, in _handle_event\n    ret = handler(auth)\n          ^^^^^^^^^^^^^\nTypeError: LiveDataNamespace.on_connect() takes 1 positional argument but 2 were given\n\nDuring handling of the above exception, another exception occurred:\n\nTraceback (most recent call last):\n  File \"C:\\Users\\HP\\AppData\\Local\\Programs\\Python\\Python311\\Lib\\site-packages\\fyers_apiv3\\FyersWebsocket\\data_ws.py\", line 1334, in __symbol_conversion\n    symbol_dict.update(symbol_dict, **symbol_value[0])\n                                      ~~~~~~~~~~~~^^^\nTypeError: 'NoneType' object is not subscriptable","exception_name":"TypeError"}
{"level":"ERROR","location":"[unsubscribe:1756] data_ws","message":"11","timestamp":"2024-04-12 11:20:39,280+0530","service":"FyersDataSocket","exception":"Traceback (most recent call last):\n  File \"C:\\Users\\HP\\AppData\\Local\\Programs\\Python\\Python311\\Lib\\site-packages\\flask_socketio\\__init__.py\", line 823, in _handle_event\n    ret = handler(auth)\n          ^^^^^^^^^^^^^\nTypeError: LiveDataNamespace.on_connect() takes 1 positional argument but 2 were given\n\nDuring handling of the above exception, another exception occurred:\n\nTraceback (most recent call last):\n  File \"C:\\Users\\HP\\AppData\\Local\\Programs\\Python\\Python311\\Lib\\site-packages\\fyers_apiv3\\FyersWebsocket\\data_ws.py\", line 1733, in unsubscribe\n    if symb not in self.scrips_count[self.channel_num]:\n                   ~~~~~~~~~~~~~~~~~^^^^^^^^^^^^^^^^^^\nKeyError: 11","exception_name":"KeyError"}
{"level":"ERROR","location":"[__datafeed_resp:1262] data_ws","message":"'sf|nse_cm|9480'","timestamp":"2024-04-12 11:20:39,735+0530","service":"FyersDataSocket","exception":"Traceback (most recent call last):\n  File \"C:\\Users\\HP\\AppData\\Local\\Programs\\Python\\Python311\\Lib\\site-packages\\fyers_apiv3\\FyersWebsocket\\data_ws.py\", line 1158, in __datafeed_resp\n    self.resp[topic_name][\"symbol\"] = self.symbol_token[topic_name]\n                                      ~~~~~~~~~~~~~~~~~^^^^^^^^^^^^\nKeyError: 'sf|nse_cm|9480'","exception_name":"KeyError"}
{"level":"ERROR","location":"[__datafeed_resp:1262] data_ws","message":"'sf|nse_cm|9480'","timestamp":"2024-04-12 11:20:40,077+0530","service":"FyersDataSocket","exception":"Traceback (most recent call last):\n  File \"C:\\Users\\HP\\AppData\\Local\\Programs\\Python\\Python311\\Lib\\site-packages\\fyers_apiv3\\FyersWebsocket\\data_ws.py\", line 1158, in __datafeed_resp\n    self.resp[topic_name][\"symbol\"] = self.symbol_token[topic_name]\n                                      ~~~~~~~~~~~~~~~~~^^^^^^^^^^^^\nKeyError: 'sf|nse_cm|9480'","exception_name":"KeyError"}
{"level":"ERROR","location":"[unsubscribe:1756] data_ws","message":"11","timestamp":"2024-04-12 11:21:56,381+0530","service":"FyersDataSocket","exception":"Traceback (most recent call last):\n  File \"C:\\Users\\HP\\AppData\\Local\\Programs\\Python\\Python311\\Lib\\site-packages\\flask_socketio\\__init__.py\", line 823, in _handle_event\n    ret = handler(auth)\n          ^^^^^^^^^^^^^\nTypeError: LiveDataNamespace.on_connect() takes 1 positional argument but 2 were given\n\nDuring handling of the above exception, another exception occurred:\n\nTraceback (most recent call last):\n  File \"C:\\Users\\HP\\AppData\\Local\\Programs\\Python\\Python311\\Lib\\site-packages\\fyers_apiv3\\FyersWebsocket\\data_ws.py\", line 1733, in unsubscribe\n    if symb not in self.scrips_count[self.channel_num]:\n                   ~~~~~~~~~~~~~~~~~^^^^^^^^^^^^^^^^^^\nKeyError: 11","exception_name":"KeyError"}
{"level":"ERROR","location":"[__datafeed_resp:1262] data_ws","message":"'sf|nse_cm|3411'","timestamp":"2024-04-12 11:21:57,058+0530","service":"FyersDataSocket","exception":"Traceback (most recent call last):\n  File \"C:\\Users\\HP\\AppData\\Local\\Programs\\Python\\Python311\\Lib\\site-packages\\fyers_apiv3\\FyersWebsocket\\data_ws.py\", line 1158, in __datafeed_resp\n    self.resp[topic_name][\"symbol\"] = self.symbol_token[topic_name]\n                                      ~~~~~~~~~~~~~~~~~^^^^^^^^^^^^\nKeyError: 'sf|nse_cm|3411'","exception_name":"KeyError"}
{"level":"ERROR","location":"[__datafeed_resp:1262] data_ws","message":"'sf|nse_cm|3411'","timestamp":"2024-04-12 11:21:58,223+0530","service":"FyersDataSocket","exception":"Traceback (most recent call last):\n  File \"C:\\Users\\HP\\AppData\\Local\\Programs\\Python\\Python311\\Lib\\site-packages\\fyers_apiv3\\FyersWebsocket\\data_ws.py\", line 1158, in __datafeed_resp\n    self.resp[topic_name][\"symbol\"] = self.symbol_token[topic_name]\n                                      ~~~~~~~~~~~~~~~~~^^^^^^^^^^^^\nKeyError: 'sf|nse_cm|3411'","exception_name":"KeyError"}
{"level":"ERROR","location":"[on_close:1547] data_ws","message":"cannot join current thread","timestamp":"2024-04-12 11:26:10,911+0530","service":"FyersDataSocket","exception":"Traceback (most recent call last):\n  File \"C:\\Users\\HP\\AppData\\Local\\Programs\\Python\\Python311\\Lib\\site-packages\\fyers_apiv3\\FyersWebsocket\\data_ws.py\", line 1543, in on_close\n    self.OnClose(message)\n  File \"E:\\Github\\Stock-analyzing-website\\Back_end\\live_stock.py\", line 64, in onclose\n    fyers.close_connection()\n  File \"C:\\Users\\HP\\AppData\\Local\\Programs\\Python\\Python311\\Lib\\site-packages\\fyers_apiv3\\FyersWebsocket\\data_ws.py\", line 1677, in close_connection\n    self.ws_thread.join()\n  File \"C:\\Users\\HP\\AppData\\Local\\Programs\\Python\\Python311\\Lib\\threading.py\", line 1109, in join\n    raise RuntimeError(\"cannot join current thread\")\nRuntimeError: cannot join current thread","exception_name":"RuntimeError"}
{"level":"ERROR","location":"[on_close:1547] data_ws","message":"cannot join current thread","timestamp":"2024-04-12 12:14:49,202+0530","service":"FyersDataSocket","exception":"Traceback (most recent call last):\n  File \"C:\\Users\\HP\\AppData\\Local\\Programs\\Python\\Python311\\Lib\\site-packages\\fyers_apiv3\\FyersWebsocket\\data_ws.py\", line 1543, in on_close\n    self.OnClose(message)\n  File \"E:\\Github\\Stock-analyzing-website\\Back_end\\live_stock.py\", line 64, in onclose\n    fyers.close_connection()\n  File \"C:\\Users\\HP\\AppData\\Local\\Programs\\Python\\Python311\\Lib\\site-packages\\fyers_apiv3\\FyersWebsocket\\data_ws.py\", line 1677, in close_connection\n    self.ws_thread.join()\n  File \"C:\\Users\\HP\\AppData\\Local\\Programs\\Python\\Python311\\Lib\\threading.py\", line 1109, in join\n    raise RuntimeError(\"cannot join current thread\")\nRuntimeError: cannot join current thread","exception_name":"RuntimeError"}
{"level":"ERROR","location":"[on_close:1547] data_ws","message":"cannot join current thread","timestamp":"2024-04-12 12:15:12,304+0530","service":"FyersDataSocket","exception":"Traceback (most recent call last):\n  File \"C:\\Users\\HP\\AppData\\Local\\Programs\\Python\\Python311\\Lib\\site-packages\\fyers_apiv3\\FyersWebsocket\\data_ws.py\", line 1543, in on_close\n    self.OnClose(message)\n  File \"E:\\Github\\Stock-analyzing-website\\Back_end\\live_stock.py\", line 64, in onclose\n    fyers.close_connection()\n  File \"C:\\Users\\HP\\AppData\\Local\\Programs\\Python\\Python311\\Lib\\site-packages\\fyers_apiv3\\FyersWebsocket\\data_ws.py\", line 1677, in close_connection\n    self.ws_thread.join()\n  File \"C:\\Users\\HP\\AppData\\Local\\Programs\\Python\\Python311\\Lib\\threading.py\", line 1109, in join\n    raise RuntimeError(\"cannot join current thread\")\nRuntimeError: cannot join current thread","exception_name":"RuntimeError"}
{"level":"ERROR","location":"[on_close:1547] data_ws","message":"cannot join current thread","timestamp":"2024-04-12 12:15:52,812+0530","service":"FyersDataSocket","exception":"Traceback (most recent call last):\n  File \"C:\\Users\\HP\\AppData\\Local\\Programs\\Python\\Python311\\Lib\\site-packages\\fyers_apiv3\\FyersWebsocket\\data_ws.py\", line 1543, in on_close\n    self.OnClose(message)\n  File \"E:\\Github\\Stock-analyzing-website\\Back_end\\live_stock.py\", line 64, in onclose\n    fyers.close_connection()\n  File \"C:\\Users\\HP\\AppData\\Local\\Programs\\Python\\Python311\\Lib\\site-packages\\fyers_apiv3\\FyersWebsocket\\data_ws.py\", line 1677, in close_connection\n    self.ws_thread.join()\n  File \"C:\\Users\\HP\\AppData\\Local\\Programs\\Python\\Python311\\Lib\\threading.py\", line 1109, in join\n    raise RuntimeError(\"cannot join current thread\")\nRuntimeError: cannot join current thread","exception_name":"RuntimeError"}
{"level":"ERROR","location":"[on_close:1547] data_ws","message":"cannot join current thread","timestamp":"2024-05-14 10:24:49,788+0530","service":"FyersDataSocket","exception":"Traceback (most recent call last):\n  File \"C:\\Users\\HP\\AppData\\Local\\Programs\\Python\\Python311\\Lib\\site-packages\\fyers_apiv3\\FyersWebsocket\\data_ws.py\", line 1543, in on_close\n    self.OnClose(message)\n  File \"E:\\Github\\Stock-analyzing-website\\Back_end\\live_stock.py\", line 65, in onclose\n    fyers.close_connection()\n  File \"C:\\Users\\HP\\AppData\\Local\\Programs\\Python\\Python311\\Lib\\site-packages\\fyers_apiv3\\FyersWebsocket\\data_ws.py\", line 1677, in close_connection\n    self.ws_thread.join()\n  File \"C:\\Users\\HP\\AppData\\Local\\Programs\\Python\\Python311\\Lib\\threading.py\", line 1109, in join\n    raise RuntimeError(\"cannot join current thread\")\nRuntimeError: cannot join current thread","exception_name":"RuntimeError"}
{"level":"ERROR","location":"[unsubscribe:1756] data_ws","message":"11","timestamp":"2024-05-14 10:30:16,916+0530","service":"FyersDataSocket","exception":"Traceback (most recent call last):\n  File \"C:\\Users\\HP\\AppData\\Local\\Programs\\Python\\Python311\\Lib\\site-packages\\flask_socketio\\__init__.py\", line 823, in _handle_event\n    ret = handler(auth)\n          ^^^^^^^^^^^^^\nTypeError: LiveDataNamespace.on_connect() takes 1 positional argument but 2 were given\n\nDuring handling of the above exception, another exception occurred:\n\nTraceback (most recent call last):\n  File \"C:\\Users\\HP\\AppData\\Local\\Programs\\Python\\Python311\\Lib\\site-packages\\fyers_apiv3\\FyersWebsocket\\data_ws.py\", line 1733, in unsubscribe\n    if symb not in self.scrips_count[self.channel_num]:\n                   ~~~~~~~~~~~~~~~~~^^^^^^^^^^^^^^^^^^\nKeyError: 11","exception_name":"KeyError"}
{"level":"ERROR","location":"[on_close:1547] data_ws","message":"cannot join current thread","timestamp":"2024-05-14 10:39:17,532+0530","service":"FyersDataSocket","exception":"Traceback (most recent call last):\n  File \"C:\\Users\\HP\\AppData\\Local\\Programs\\Python\\Python311\\Lib\\site-packages\\fyers_apiv3\\FyersWebsocket\\data_ws.py\", line 1543, in on_close\n    self.OnClose(message)\n  File \"E:\\Github\\Stock-analyzing-website\\Back_end\\live_stock.py\", line 65, in onclose\n    fyers.close_connection()\n  File \"C:\\Users\\HP\\AppData\\Local\\Programs\\Python\\Python311\\Lib\\site-packages\\fyers_apiv3\\FyersWebsocket\\data_ws.py\", line 1677, in close_connection\n    self.ws_thread.join()\n  File \"C:\\Users\\HP\\AppData\\Local\\Programs\\Python\\Python311\\Lib\\threading.py\", line 1109, in join\n    raise RuntimeError(\"cannot join current thread\")\nRuntimeError: cannot join current thread","exception_name":"RuntimeError"}
{"level":"ERROR","location":"[on_close:1547] data_ws","message":"cannot join current thread","timestamp":"2024-05-14 10:41:39,106+0530","service":"FyersDataSocket","exception":"Traceback (most recent call last):\n  File \"C:\\Users\\HP\\AppData\\Local\\Programs\\Python\\Python311\\Lib\\site-packages\\fyers_apiv3\\FyersWebsocket\\data_ws.py\", line 1543, in on_close\n    self.OnClose(message)\n  File \"E:\\Github\\Stock-analyzing-website\\Back_end\\live_stock.py\", line 65, in onclose\n    fyers.close_connection()\n  File \"C:\\Users\\HP\\AppData\\Local\\Programs\\Python\\Python311\\Lib\\site-packages\\fyers_apiv3\\FyersWebsocket\\data_ws.py\", line 1677, in close_connection\n    self.ws_thread.join()\n  File \"C:\\Users\\HP\\AppData\\Local\\Programs\\Python\\Python311\\Lib\\threading.py\", line 1109, in join\n    raise RuntimeError(\"cannot join current thread\")\nRuntimeError: cannot join current thread","exception_name":"RuntimeError"}
{"level":"ERROR","location":"[on_close:1547] data_ws","message":"cannot join current thread","timestamp":"2024-05-14 10:42:10,983+0530","service":"FyersDataSocket","exception":"Traceback (most recent call last):\n  File \"C:\\Users\\HP\\AppData\\Local\\Programs\\Python\\Python311\\Lib\\site-packages\\fyers_apiv3\\FyersWebsocket\\data_ws.py\", line 1543, in on_close\n    self.OnClose(message)\n  File \"E:\\Github\\Stock-analyzing-website\\Back_end\\live_stock.py\", line 65, in onclose\n    fyers.close_connection()\n  File \"C:\\Users\\HP\\AppData\\Local\\Programs\\Python\\Python311\\Lib\\site-packages\\fyers_apiv3\\FyersWebsocket\\data_ws.py\", line 1677, in close_connection\n    self.ws_thread.join()\n  File \"C:\\Users\\HP\\AppData\\Local\\Programs\\Python\\Python311\\Lib\\threading.py\", line 1109, in join\n    raise RuntimeError(\"cannot join current thread\")\nRuntimeError: cannot join current thread","exception_name":"RuntimeError"}
{"level":"ERROR","location":"[on_close:1547] data_ws","message":"cannot join current thread","timestamp":"2024-05-14 10:43:33,910+0530","service":"FyersDataSocket","exception":"Traceback (most recent call last):\n  File \"C:\\Users\\HP\\AppData\\Local\\Programs\\Python\\Python311\\Lib\\site-packages\\fyers_apiv3\\FyersWebsocket\\data_ws.py\", line 1543, in on_close\n    self.OnClose(message)\n  File \"E:\\Github\\Stock-analyzing-website\\Back_end\\live_stock.py\", line 65, in onclose\n    fyers.close_connection()\n  File \"C:\\Users\\HP\\AppData\\Local\\Programs\\Python\\Python311\\Lib\\site-packages\\fyers_apiv3\\FyersWebsocket\\data_ws.py\", line 1677, in close_connection\n    self.ws_thread.join()\n  File \"C:\\Users\\HP\\AppData\\Local\\Programs\\Python\\Python311\\Lib\\threading.py\", line 1109, in join\n    raise RuntimeError(\"cannot join current thread\")\nRuntimeError: cannot join current thread","exception_name":"RuntimeError"}
{"level":"ERROR","location":"[symbol_to_hsmtoken:128] data_ws","message":"'fyToken'","timestamp":"2024-05-14 10:43:38,118+0530","service":"FyersDataSocket","exception":"Traceback (most recent call last):\n  File \"C:\\Users\\HP\\AppData\\Local\\Programs\\Python\\Python311\\Lib\\site-packages\\flask_socketio\\__init__.py\", line 823, in _handle_event\n    ret = handler(auth)\n          ^^^^^^^^^^^^^\nTypeError: LiveDataNamespace.on_connect() takes 1 positional argument but 2 were given\n\nDuring handling of the above exception, another exception occurred:\n\nTraceback (most recent call last):\n  File \"C:\\Users\\HP\\AppData\\Local\\Programs\\Python\\Python311\\Lib\\site-packages\\fyers_apiv3\\FyersWebsocket\\data_ws.py\", line 87, in symbol_to_hsmtoken\n    values[\"fyToken\"] = data[\"v\"][\"fyToken\"]\n                        ~~~~~~~~~^^^^^^^^^^^\nKeyError: 'fyToken'","exception_name":"KeyError"}
{"level":"ERROR","location":"[__symbol_conversion:1366] data_ws","message":"'NoneType' object is not subscriptable","timestamp":"2024-05-14 10:43:38,120+0530","service":"FyersDataSocket","exception":"Traceback (most recent call last):\n  File \"C:\\Users\\HP\\AppData\\Local\\Programs\\Python\\Python311\\Lib\\site-packages\\flask_socketio\\__init__.py\", line 823, in _handle_event\n    ret = handler(auth)\n          ^^^^^^^^^^^^^\nTypeError: LiveDataNamespace.on_connect() takes 1 positional argument but 2 were given\n\nDuring handling of the above exception, another exception occurred:\n\nTraceback (most recent call last):\n  File \"C:\\Users\\HP\\AppData\\Local\\Programs\\Python\\Python311\\Lib\\site-packages\\fyers_apiv3\\FyersWebsocket\\data_ws.py\", line 1334, in __symbol_conversion\n    symbol_dict.update(symbol_dict, **symbol_value[0])\n                                      ~~~~~~~~~~~~^^^\nTypeError: 'NoneType' object is not subscriptable","exception_name":"TypeError"}
{"level":"ERROR","location":"[symbol_to_hsmtoken:128] data_ws","message":"'fyToken'","timestamp":"2024-05-14 10:43:40,946+0530","service":"FyersDataSocket","exception":"Traceback (most recent call last):\n  File \"C:\\Users\\HP\\AppData\\Local\\Programs\\Python\\Python311\\Lib\\site-packages\\flask_socketio\\__init__.py\", line 823, in _handle_event\n    ret = handler(auth)\n          ^^^^^^^^^^^^^\nTypeError: LiveDataNamespace.on_connect() takes 1 positional argument but 2 were given\n\nDuring handling of the above exception, another exception occurred:\n\nTraceback (most recent call last):\n  File \"C:\\Users\\HP\\AppData\\Local\\Programs\\Python\\Python311\\Lib\\site-packages\\fyers_apiv3\\FyersWebsocket\\data_ws.py\", line 87, in symbol_to_hsmtoken\n    values[\"fyToken\"] = data[\"v\"][\"fyToken\"]\n                        ~~~~~~~~~^^^^^^^^^^^\nKeyError: 'fyToken'","exception_name":"KeyError"}
{"level":"ERROR","location":"[__symbol_conversion:1366] data_ws","message":"'NoneType' object is not subscriptable","timestamp":"2024-05-14 10:43:40,948+0530","service":"FyersDataSocket","exception":"Traceback (most recent call last):\n  File \"C:\\Users\\HP\\AppData\\Local\\Programs\\Python\\Python311\\Lib\\site-packages\\flask_socketio\\__init__.py\", line 823, in _handle_event\n    ret = handler(auth)\n          ^^^^^^^^^^^^^\nTypeError: LiveDataNamespace.on_connect() takes 1 positional argument but 2 were given\n\nDuring handling of the above exception, another exception occurred:\n\nTraceback (most recent call last):\n  File \"C:\\Users\\HP\\AppData\\Local\\Programs\\Python\\Python311\\Lib\\site-packages\\fyers_apiv3\\FyersWebsocket\\data_ws.py\", line 1334, in __symbol_conversion\n    symbol_dict.update(symbol_dict, **symbol_value[0])\n                                      ~~~~~~~~~~~~^^^\nTypeError: 'NoneType' object is not subscriptable","exception_name":"TypeError"}
{"level":"ERROR","location":"[on_close:1547] data_ws","message":"cannot join current thread","timestamp":"2024-05-14 10:43:49,795+0530","service":"FyersDataSocket","exception":"Traceback (most recent call last):\n  File \"C:\\Users\\HP\\AppData\\Local\\Programs\\Python\\Python311\\Lib\\site-packages\\fyers_apiv3\\FyersWebsocket\\data_ws.py\", line 1543, in on_close\n    self.OnClose(message)\n  File \"E:\\Github\\Stock-analyzing-website\\Back_end\\live_stock.py\", line 65, in onclose\n    fyers.close_connection()\n  File \"C:\\Users\\HP\\AppData\\Local\\Programs\\Python\\Python311\\Lib\\site-packages\\fyers_apiv3\\FyersWebsocket\\data_ws.py\", line 1677, in close_connection\n    self.ws_thread.join()\n  File \"C:\\Users\\HP\\AppData\\Local\\Programs\\Python\\Python311\\Lib\\threading.py\", line 1109, in join\n    raise RuntimeError(\"cannot join current thread\")\nRuntimeError: cannot join current thread","exception_name":"RuntimeError"}
{"level":"ERROR","location":"[__datafeed_resp:1262] data_ws","message":"'sf|nse_cm|3411'","timestamp":"2024-05-14 10:44:03,477+0530","service":"FyersDataSocket","exception":"Traceback (most recent call last):\n  File \"C:\\Users\\HP\\AppData\\Local\\Programs\\Python\\Python311\\Lib\\site-packages\\fyers_apiv3\\FyersWebsocket\\data_ws.py\", line 1158, in __datafeed_resp\n    self.resp[topic_name][\"symbol\"] = self.symbol_token[topic_name]\n                                      ~~~~~~~~~~~~~~~~~^^^^^^^^^^^^\nKeyError: 'sf|nse_cm|3411'","exception_name":"KeyError"}
{"level":"ERROR","location":"[on_close:1547] data_ws","message":"cannot join current thread","timestamp":"2024-05-14 10:44:26,287+0530","service":"FyersDataSocket","exception":"Traceback (most recent call last):\n  File \"C:\\Users\\HP\\AppData\\Local\\Programs\\Python\\Python311\\Lib\\site-packages\\fyers_apiv3\\FyersWebsocket\\data_ws.py\", line 1543, in on_close\n    self.OnClose(message)\n  File \"E:\\Github\\Stock-analyzing-website\\Back_end\\live_stock.py\", line 65, in onclose\n    fyers.close_connection()\n  File \"C:\\Users\\HP\\AppData\\Local\\Programs\\Python\\Python311\\Lib\\site-packages\\fyers_apiv3\\FyersWebsocket\\data_ws.py\", line 1677, in close_connection\n    self.ws_thread.join()\n  File \"C:\\Users\\HP\\AppData\\Local\\Programs\\Python\\Python311\\Lib\\threading.py\", line 1109, in join\n    raise RuntimeError(\"cannot join current thread\")\nRuntimeError: cannot join current thread","exception_name":"RuntimeError"}
{"level":"ERROR","location":"[on_close:1547] data_ws","message":"cannot join current thread","timestamp":"2024-05-14 10:45:44,538+0530","service":"FyersDataSocket","exception":"Traceback (most recent call last):\n  File \"C:\\Users\\HP\\AppData\\Local\\Programs\\Python\\Python311\\Lib\\site-packages\\fyers_apiv3\\FyersWebsocket\\data_ws.py\", line 1543, in on_close\n    self.OnClose(message)\n  File \"E:\\Github\\Stock-analyzing-website\\Back_end\\live_stock.py\", line 65, in onclose\n    fyers.close_connection()\n  File \"C:\\Users\\HP\\AppData\\Local\\Programs\\Python\\Python311\\Lib\\site-packages\\fyers_apiv3\\FyersWebsocket\\data_ws.py\", line 1677, in close_connection\n    self.ws_thread.join()\n  File \"C:\\Users\\HP\\AppData\\Local\\Programs\\Python\\Python311\\Lib\\threading.py\", line 1109, in join\n    raise RuntimeError(\"cannot join current thread\")\nRuntimeError: cannot join current thread","exception_name":"RuntimeError"}
{"level":"ERROR","location":"[on_close:1547] data_ws","message":"cannot join current thread","timestamp":"2024-05-14 10:48:41,906+0530","service":"FyersDataSocket","exception":"Traceback (most recent call last):\n  File \"C:\\Users\\HP\\AppData\\Local\\Programs\\Python\\Python311\\Lib\\site-packages\\fyers_apiv3\\FyersWebsocket\\data_ws.py\", line 1543, in on_close\n    self.OnClose(message)\n  File \"E:\\Github\\Stock-analyzing-website\\Back_end\\live_stock.py\", line 65, in onclose\n    fyers.close_connection()\n  File \"C:\\Users\\HP\\AppData\\Local\\Programs\\Python\\Python311\\Lib\\site-packages\\fyers_apiv3\\FyersWebsocket\\data_ws.py\", line 1677, in close_connection\n    self.ws_thread.join()\n  File \"C:\\Users\\HP\\AppData\\Local\\Programs\\Python\\Python311\\Lib\\threading.py\", line 1109, in join\n    raise RuntimeError(\"cannot join current thread\")\nRuntimeError: cannot join current thread","exception_name":"RuntimeError"}
{"level":"ERROR","location":"[on_close:1547] data_ws","message":"cannot join current thread","timestamp":"2024-05-14 10:49:27,696+0530","service":"FyersDataSocket","exception":"Traceback (most recent call last):\n  File \"C:\\Users\\HP\\AppData\\Local\\Programs\\Python\\Python311\\Lib\\site-packages\\fyers_apiv3\\FyersWebsocket\\data_ws.py\", line 1543, in on_close\n    self.OnClose(message)\n  File \"E:\\Github\\Stock-analyzing-website\\Back_end\\live_stock.py\", line 65, in onclose\n    fyers.close_connection()\n  File \"C:\\Users\\HP\\AppData\\Local\\Programs\\Python\\Python311\\Lib\\site-packages\\fyers_apiv3\\FyersWebsocket\\data_ws.py\", line 1677, in close_connection\n    self.ws_thread.join()\n  File \"C:\\Users\\HP\\AppData\\Local\\Programs\\Python\\Python311\\Lib\\threading.py\", line 1109, in join\n    raise RuntimeError(\"cannot join current thread\")\nRuntimeError: cannot join current thread","exception_name":"RuntimeError"}
{"level":"ERROR","location":"[on_close:1547] data_ws","message":"cannot join current thread","timestamp":"2024-05-14 10:54:36,442+0530","service":"FyersDataSocket","exception":"Traceback (most recent call last):\n  File \"C:\\Users\\HP\\AppData\\Local\\Programs\\Python\\Python311\\Lib\\site-packages\\fyers_apiv3\\FyersWebsocket\\data_ws.py\", line 1543, in on_close\n    self.OnClose(message)\n  File \"E:\\Github\\Stock-analyzing-website\\Back_end\\live_stock.py\", line 65, in onclose\n    fyers.close_connection()\n  File \"C:\\Users\\HP\\AppData\\Local\\Programs\\Python\\Python311\\Lib\\site-packages\\fyers_apiv3\\FyersWebsocket\\data_ws.py\", line 1677, in close_connection\n    self.ws_thread.join()\n  File \"C:\\Users\\HP\\AppData\\Local\\Programs\\Python\\Python311\\Lib\\threading.py\", line 1109, in join\n    raise RuntimeError(\"cannot join current thread\")\nRuntimeError: cannot join current thread","exception_name":"RuntimeError"}
{"level":"ERROR","location":"[on_close:1547] data_ws","message":"cannot join current thread","timestamp":"2024-05-14 12:25:49,090+0530","service":"FyersDataSocket","exception":"Traceback (most recent call last):\n  File \"C:\\Users\\HP\\AppData\\Local\\Programs\\Python\\Python311\\Lib\\site-packages\\fyers_apiv3\\FyersWebsocket\\data_ws.py\", line 1543, in on_close\n    self.OnClose(message)\n  File \"E:\\Github\\Stock-analyzing-website\\Back_end\\live_stock.py\", line 65, in onclose\n    fyers.close_connection()\n  File \"C:\\Users\\HP\\AppData\\Local\\Programs\\Python\\Python311\\Lib\\site-packages\\fyers_apiv3\\FyersWebsocket\\data_ws.py\", line 1677, in close_connection\n    self.ws_thread.join()\n  File \"C:\\Users\\HP\\AppData\\Local\\Programs\\Python\\Python311\\Lib\\threading.py\", line 1109, in join\n    raise RuntimeError(\"cannot join current thread\")\nRuntimeError: cannot join current thread","exception_name":"RuntimeError"}
{"level":"ERROR","location":"[on_close:1547] data_ws","message":"cannot join current thread","timestamp":"2024-05-14 12:47:55,966+0530","service":"FyersDataSocket","exception":"Traceback (most recent call last):\n  File \"C:\\Users\\HP\\AppData\\Local\\Programs\\Python\\Python311\\Lib\\site-packages\\fyers_apiv3\\FyersWebsocket\\data_ws.py\", line 1543, in on_close\n    self.OnClose(message)\n  File \"E:\\Github\\Stock-analyzing-website\\Back_end\\live_stock.py\", line 65, in onclose\n    fyers.close_connection()\n  File \"C:\\Users\\HP\\AppData\\Local\\Programs\\Python\\Python311\\Lib\\site-packages\\fyers_apiv3\\FyersWebsocket\\data_ws.py\", line 1677, in close_connection\n    self.ws_thread.join()\n  File \"C:\\Users\\HP\\AppData\\Local\\Programs\\Python\\Python311\\Lib\\threading.py\", line 1109, in join\n    raise RuntimeError(\"cannot join current thread\")\nRuntimeError: cannot join current thread","exception_name":"RuntimeError"}
{"level":"ERROR","location":"[on_close:1547] data_ws","message":"cannot join current thread","timestamp":"2024-05-14 14:16:57,396+0530","service":"FyersDataSocket","exception":"Traceback (most recent call last):\n  File \"C:\\Users\\HP\\AppData\\Local\\Programs\\Python\\Python311\\Lib\\site-packages\\fyers_apiv3\\FyersWebsocket\\data_ws.py\", line 1543, in on_close\n    self.OnClose(message)\n  File \"E:\\Github\\Stock-analyzing-website\\Back_end\\live_stock.py\", line 65, in onclose\n    fyers.close_connection()\n  File \"C:\\Users\\HP\\AppData\\Local\\Programs\\Python\\Python311\\Lib\\site-packages\\fyers_apiv3\\FyersWebsocket\\data_ws.py\", line 1677, in close_connection\n    self.ws_thread.join()\n  File \"C:\\Users\\HP\\AppData\\Local\\Programs\\Python\\Python311\\Lib\\threading.py\", line 1109, in join\n    raise RuntimeError(\"cannot join current thread\")\nRuntimeError: cannot join current thread","exception_name":"RuntimeError"}
